Workbook

Sheet Себестойност
A1: Продукт | B1: Код | C1: Цена бр. | D1: М. ед. | E1: Отстъпка | F1: Цена нето | G1: К-во | H1: Крайна цена | I1: Фирма | J1: Обновена на | K1: ДДС 20% | L1: Крайна цена с ДДС | M1: Бележки | O1: Проверка (0,00) | Q1: Проверка:
A2: Електролизьор (500kW) | I2: =SUM(H3:H31) -> 75474.749 | M2: =SUM(L3:L31) -> 90335.963 | Q2: Sheet | R2: Цена | S2: К-во
A3: Черна ламарина 2010х1500х70 S355 (+ газово прерязване) | B3: =IFERROR(VLOOKUP($A3,[1]Други!$A:$H,2,FALSE),IFERROR(VLOOKUP($A3,[1]ИТТ!$A:$H,2,FALSE),IFERROR(VLOOKUP($A3,[1]Schrack!$A:$H,2,FALSE),IFERROR(VLOOKUP($A3,'[1]LD GmbH'!$A:$H,2,FALSE),IFERROR(VLOOKUP($A3,[1]Крисметал!$A:$H,2,FALSE),IFERROR(VLOOKUP($A3,[1]Унител!$A:$H,2,FALSE),"")))))) -> - | C3: =IFERROR(VLOOKUP($A3,[1]Други!$A:$H,3,FALSE),IFERROR(VLOOKUP($A3,[1]ИТТ!$A:$H,3,FALSE),IFERROR(VLOOKUP($A3,[1]Schrack!$A:$H,3,FALSE),IFERROR(VLOOKUP($A3,'[1]LD GmbH'!$A:$H,3,FALSE),IFERROR(VLOOKUP($A3,[1]Крисметал!$A:$H,3,FALSE),IFERROR(VLOOKUP($A3,[1]Унител!$A:$H,3,FALSE),"")))))) -> 1542.07 | D3: =IFERROR(VLOOKUP($A3,[1]Други!$A:$H,4,FALSE),IFERROR(VLOOKUP($A3,[1]ИТТ!$A:$H,4,FALSE),IFERROR(VLOOKUP($A3,[1]Schrack!$A:$H,4,FALSE),IFERROR(VLOOKUP($A3,'[1]LD GmbH'!$A:$H,4,FALSE),IFERROR(VLOOKUP($A3,[1]Крисметал!$A:$H,4,FALSE),IFERROR(VLOOKUP($A3,[1]Унител!$A:$H,4,FALSE),"")))))) -> бр. | E3: =IFERROR(VLOOKUP($A3,[1]Други!$A:$H,5,FALSE),IFERROR(VLOOKUP($A3,[1]ИТТ!$A:$H,5,FALSE),IFERROR(VLOOKUP($A3,[1]Schrack!$A:$H,5,FALSE),IFERROR(VLOOKUP($A3,'[1]LD GmbH'!$A:$H,5,FALSE),IFERROR(VLOOKUP($A3,[1]Крисметал!$A:$H,5,FALSE),IFERROR(VLOOKUP($A3,[1]Унител!$A:$H,5,FALSE),"")))))) -> 0 | F3: =IFERROR(VLOOKUP($A3,[1]Други!$A:$H,6,FALSE),IFERROR(VLOOKUP($A3,[1]ИТТ!$A:$H,6,FALSE),IFERROR(VLOOKUP($A3,[1]Schrack!$A:$H,6,FALSE),IFERROR(VLOOKUP($A3,'[1]LD GmbH'!$A:$H,6,FALSE),IFERROR(VLOOKUP($A3,[1]Крисметал!$A:$H,6,FALSE),IFERROR(VLOOKUP($A3,[1]Унител!$A:$H,6,FALSE),"")))))) -> 1542.07 | G3: =IFERROR(SUMIF(Модули!$A:$A,Себестойност!A3,Модули!$B:$B),"") -> 2 | H3: =IFERROR(F3*G3,"") -> 3084.14 | I3: =IFERROR(VLOOKUP($A3,[1]Други!$A:$H,8,FALSE),IFERROR(VLOOKUP($A3,[1]ИТТ!$A:$H,8,FALSE),IFERROR(VLOOKUP($A3,[1]Schrack!$A:$H,8,FALSE),IFERROR(VLOOKUP($A3,'[1]LD GmbH'!$A:$H,8,FALSE),IFERROR(VLOOKUP($A3,[1]Крисметал!$A:$H,8,FALSE),IFERROR(VLOOKUP($A3,[1]Унител!$A:$H,8,FALSE),"")))))) -> Ангел Стоилов - 96 АД | J3: =IFERROR(VLOOKUP($A3,[1]Други!$A:$I,9,FALSE),IFERROR(VLOOKUP($A3,[1]ИТТ!$A:$I,9,FALSE),IFERROR(VLOOKUP($A3,[1]Schrack!$A:$I,9,FALSE),IFERROR(VLOOKUP($A3,'[1]LD GmbH'!$A:$I,9,FALSE),IFERROR(VLOOKUP($A3,[1]Крисметал!$A:$I,9,FALSE),IFERROR(VLOOKUP($A3,[1]Унител!$A:$I,9,FALSE),"")))))) -> 45870 | K3: =IFERROR(VLOOKUP($A3,[1]Други!$A:$H,7,FALSE),IFERROR(VLOOKUP($A3,[1]ИТТ!$A:$H,7,FALSE),IFERROR(VLOOKUP($A3,[1]Schrack!$A:$H,7,FALSE),IFERROR(VLOOKUP($A3,'[1]LD GmbH'!$A:$H,7,FALSE),IFERROR(VLOOKUP($A3,[1]Крисметал!$A:$H,7,FALSE),IFERROR(VLOOKUP($A3,[1]Унител!$A:$H,7,FALSE),"")))))) -> 1850.484 | L3: =G3*K3 -> 3700.968 | O3: =SUMIF(Модули!$A:$A,Себестойност!A3,Модули!$B:$B)-G3 -> 0 | Q3: Модули: | R3: =SUM(Модули!F:F) -> 223986.94 | S3: =SUM(Модули!B:B) -> 4297.74
A4: Лист неръждаема стомана 316L 2500х1250х5 | B4: =IFERROR(VLOOKUP($A4,[1]Други!$A:$H,2,FALSE),IFERROR(VLOOKUP($A4,[1]ИТТ!$A:$H,2,FALSE),IFERROR(VLOOKUP($A4,[1]Schrack!$A:$H,2,FALSE),IFERROR(VLOOKUP($A4,'[1]LD GmbH'!$A:$H,2,FALSE),IFERROR(VLOOKUP($A4,[1]Крисметал!$A:$H,2,FALSE),IFERROR(VLOOKUP($A4,[1]Унител!$A:$H,2,FALSE),"")))))) -> 193101 | C4: =IFERROR(VLOOKUP($A4,[1]Други!$A:$H,3,FALSE),IFERROR(VLOOKUP($A4,[1]ИТТ!$A:$H,3,FALSE),IFERROR(VLOOKUP($A4,[1]Schrack!$A:$H,3,FALSE),IFERROR(VLOOKUP($A4,'[1]LD GmbH'!$A:$H,3,FALSE),IFERROR(VLOOKUP($A4,[1]Крисметал!$A:$H,3,FALSE),IFERROR(VLOOKUP($A4,[1]Унител!$A:$H,3,FALSE),"")))))) -> 478.7 | D4: =IFERROR(VLOOKUP($A4,[1]Други!$A:$H,4,FALSE),IFERROR(VLOOKUP($A4,[1]ИТТ!$A:$H,4,FALSE),IFERROR(VLOOKUP($A4,[1]Schrack!$A:$H,4,FALSE),IFERROR(VLOOKUP($A4,'[1]LD GmbH'!$A:$H,4,FALSE),IFERROR(VLOOKUP($A4,[1]Крисметал!$A:$H,4,FALSE),IFERROR(VLOOKUP($A4,[1]Унител!$A:$H,4,FALSE),"")))))) -> бр. | E4: =IFERROR(VLOOKUP($A4,[1]Други!$A:$H,5,FALSE),IFERROR(VLOOKUP($A4,[1]ИТТ!$A:$H,5,FALSE),IFERROR(VLOOKUP($A4,[1]Schrack!$A:$H,5,FALSE),IFERROR(VLOOKUP($A4,'[1]LD GmbH'!$A:$H,5,FALSE),IFERROR(VLOOKUP($A4,[1]Крисметал!$A:$H,5,FALSE),IFERROR(VLOOKUP($A4,[1]Унител!$A:$H,5,FALSE),"")))))) -> 0 | F4: =IFERROR(VLOOKUP($A4,[1]Други!$A:$H,6,FALSE),IFERROR(VLOOKUP($A4,[1]ИТТ!$A:$H,6,FALSE),IFERROR(VLOOKUP($A4,[1]Schrack!$A:$H,6,FALSE),IFERROR(VLOOKUP($A4,'[1]LD GmbH'!$A:$H,6,FALSE),IFERROR(VLOOKUP($A4,[1]Крисметал!$A:$H,6,FALSE),IFERROR(VLOOKUP($A4,[1]Унител!$A:$H,6,FALSE),"")))))) -> 478.7 | G4: =IFERROR(SUMIF(Модули!$A:$A,Себестойност!A4,Модули!$B:$B),"") -> 2 | H4: =IFERROR(F4*G4,"") -> 957.4 | I4: =IFERROR(VLOOKUP($A4,[1]Други!$A:$H,8,FALSE),IFERROR(VLOOKUP($A4,[1]ИТТ!$A:$H,8,FALSE),IFERROR(VLOOKUP($A4,[1]Schrack!$A:$H,8,FALSE),IFERROR(VLOOKUP($A4,'[1]LD GmbH'!$A:$H,8,FALSE),IFERROR(VLOOKUP($A4,[1]Крисметал!$A:$H,8,FALSE),IFERROR(VLOOKUP($A4,[1]Унител!$A:$H,8,FALSE),"")))))) -> Филипекс | J4: =IFERROR(VLOOKUP($A4,[1]Други!$A:$I,9,FALSE),IFERROR(VLOOKUP($A4,[1]ИТТ!$A:$I,9,FALSE),IFERROR(VLOOKUP($A4,[1]Schrack!$A:$I,9,FALSE),IFERROR(VLOOKUP($A4,'[1]LD GmbH'!$A:$I,9,FALSE),IFERROR(VLOOKUP($A4,[1]Крисметал!$A:$I,9,FALSE),IFERROR(VLOOKUP($A4,[1]Унител!$A:$I,9,FALSE),"")))))) -> 45875 | K4: =IFERROR(VLOOKUP($A4,[1]Други!$A:$H,7,FALSE),IFERROR(VLOOKUP($A4,[1]ИТТ!$A:$H,7,FALSE),IFERROR(VLOOKUP($A4,[1]Schrack!$A:$H,7,FALSE),IFERROR(VLOOKUP($A4,'[1]LD GmbH'!$A:$H,7,FALSE),IFERROR(VLOOKUP($A4,[1]Крисметал!$A:$H,7,FALSE),IFERROR(VLOOKUP($A4,[1]Унител!$A:$H,7,FALSE),"")))))) -> 574.44 | L4: =G4*K4 -> 1148.88 | O4: =SUMIF(Модули!$A:$A,Себестойност!A4,Модули!$B:$B)-G4 -> 0 | Q4: Себестойност: | R4: =H346 -> 223986.94 | S4: =SUM(G:G) -> 4297.74
A5: Лист неръждаема стомана 316L 2500х1250х2 | B5: =IFERROR(VLOOKUP($A5,[1]Други!$A:$H,2,FALSE),IFERROR(VLOOKUP($A5,[1]ИТТ!$A:$H,2,FALSE),IFERROR(VLOOKUP($A5,[1]Schrack!$A:$H,2,FALSE),IFERROR(VLOOKUP($A5,'[1]LD GmbH'!$A:$H,2,FALSE),IFERROR(VLOOKUP($A5,[1]Крисметал!$A:$H,2,FALSE),IFERROR(VLOOKUP($A5,[1]Унител!$A:$H,2,FALSE),"")))))) -> 193311 | C5: =IFERROR(VLOOKUP($A5,[1]Други!$A:$H,3,FALSE),IFERROR(VLOOKUP($A5,[1]ИТТ!$A:$H,3,FALSE),IFERROR(VLOOKUP($A5,[1]Schrack!$A:$H,3,FALSE),IFERROR(VLOOKUP($A5,'[1]LD GmbH'!$A:$H,3,FALSE),IFERROR(VLOOKUP($A5,[1]Крисметал!$A:$H,3,FALSE),IFERROR(VLOOKUP($A5,[1]Унител!$A:$H,3,FALSE),"")))))) -> 191.48 | D5: =IFERROR(VLOOKUP($A5,[1]Други!$A:$H,4,FALSE),IFERROR(VLOOKUP($A5,[1]ИТТ!$A:$H,4,FALSE),IFERROR(VLOOKUP($A5,[1]Schrack!$A:$H,4,FALSE),IFERROR(VLOOKUP($A5,'[1]LD GmbH'!$A:$H,4,FALSE),IFERROR(VLOOKUP($A5,[1]Крисметал!$A:$H,4,FALSE),IFERROR(VLOOKUP($A5,[1]Унител!$A:$H,4,FALSE),"")))))) -> бр. | E5: =IFERROR(VLOOKUP($A5,[1]Други!$A:$H,5,FALSE),IFERROR(VLOOKUP($A5,[1]ИТТ!$A:$H,5,FALSE),IFERROR(VLOOKUP($A5,[1]Schrack!$A:$H,5,FALSE),IFERROR(VLOOKUP($A5,'[1]LD GmbH'!$A:$H,5,FALSE),IFERROR(VLOOKUP($A5,[1]Крисметал!$A:$H,5,FALSE),IFERROR(VLOOKUP($A5,[1]Унител!$A:$H,5,FALSE),"")))))) -> 0 | F5: =IFERROR(VLOOKUP($A5,[1]Други!$A:$H,6,FALSE),IFERROR(VLOOKUP($A5,[1]ИТТ!$A:$H,6,FALSE),IFERROR(VLOOKUP($A5,[1]Schrack!$A:$H,6,FALSE),IFERROR(VLOOKUP($A5,'[1]LD GmbH'!$A:$H,6,FALSE),IFERROR(VLOOKUP($A5,[1]Крисметал!$A:$H,6,FALSE),IFERROR(VLOOKUP($A5,[1]Унител!$A:$H,6,FALSE),"")))))) -> 191.48 | G5: =IFERROR(SUMIF(Модули!$A:$A,Себестойност!A5,Модули!$B:$B),"") -> 46 | H5: =IFERROR(F5*G5,"") -> 8808.08 | I5: =IFERROR(VLOOKUP($A5,[1]Други!$A:$H,8,FALSE),IFERROR(VLOOKUP($A5,[1]ИТТ!$A:$H,8,FALSE),IFERROR(VLOOKUP($A5,[1]Schrack!$A:$H,8,FALSE),IFERROR(VLOOKUP($A5,'[1]LD GmbH'!$A:$H,8,FALSE),IFERROR(VLOOKUP($A5,[1]Крисметал!$A:$H,8,FALSE),IFERROR(VLOOKUP($A5,[1]Унител!$A:$H,8,FALSE),"")))))) -> Филипекс | J5: =IFERROR(VLOOKUP($A5,[1]Други!$A:$I,9,FALSE),IFERROR(VLOOKUP($A5,[1]ИТТ!$A:$I,9,FALSE),IFERROR(VLOOKUP($A5,[1]Schrack!$A:$I,9,FALSE),IFERROR(VLOOKUP($A5,'[1]LD GmbH'!$A:$I,9,FALSE),IFERROR(VLOOKUP($A5,[1]Крисметал!$A:$I,9,FALSE),IFERROR(VLOOKUP($A5,[1]Унител!$A:$I,9,FALSE),"")))))) -> 45875 | K5: =IFERROR(VLOOKUP($A5,[1]Други!$A:$H,7,FALSE),IFERROR(VLOOKUP($A5,[1]ИТТ!$A:$H,7,FALSE),IFERROR(VLOOKUP($A5,[1]Schrack!$A:$H,7,FALSE),IFERROR(VLOOKUP($A5,'[1]LD GmbH'!$A:$H,7,FALSE),IFERROR(VLOOKUP($A5,[1]Крисметал!$A:$H,7,FALSE),IFERROR(VLOOKUP($A5,[1]Унител!$A:$H,7,FALSE),"")))))) -> 229.776 | L5: =G5*K5 -> 10569.696 | O5: =SUMIF(Модули!$A:$A,Себестойност!A5,Модули!$B:$B)-G5 -> 0
A6: Sealing Gasket Modified PTFE 1060х900х5 (+транспорт) (+мито 6,5%) | B6: =IFERROR(VLOOKUP($A6,[1]Други!$A:$H,2,FALSE),IFERROR(VLOOKUP($A6,[1]ИТТ!$A:$H,2,FALSE),IFERROR(VLOOKUP($A6,[1]Schrack!$A:$H,2,FALSE),IFERROR(VLOOKUP($A6,'[1]LD GmbH'!$A:$H,2,FALSE),IFERROR(VLOOKUP($A6,[1]Крисметал!$A:$H,2,FALSE),IFERROR(VLOOKUP($A6,[1]Унител!$A:$H,2,FALSE),"")))))) -> - | C6: =IFERROR(VLOOKUP($A6,[1]Други!$A:$H,3,FALSE),IFERROR(VLOOKUP($A6,[1]ИТТ!$A:$H,3,FALSE),IFERROR(VLOOKUP($A6,[1]Schrack!$A:$H,3,FALSE),IFERROR(VLOOKUP($A6,'[1]LD GmbH'!$A:$H,3,FALSE),IFERROR(VLOOKUP($A6,[1]Крисметал!$A:$H,3,FALSE),IFERROR(VLOOKUP($A6,[1]Унител!$A:$H,3,FALSE),"")))))) -> 86.06265 | D6: =IFERROR(VLOOKUP($A6,[1]Други!$A:$H,4,FALSE),IFERROR(VLOOKUP($A6,[1]ИТТ!$A:$H,4,FALSE),IFERROR(VLOOKUP($A6,[1]Schrack!$A:$H,4,FALSE),IFERROR(VLOOKUP($A6,'[1]LD GmbH'!$A:$H,4,FALSE),IFERROR(VLOOKUP($A6,[1]Крисметал!$A:$H,4,FALSE),IFERROR(VLOOKUP($A6,[1]Унител!$A:$H,4,FALSE),"")))))) -> бр. | E6: =IFERROR(VLOOKUP($A6,[1]Други!$A:$H,5,FALSE),IFERROR(VLOOKUP($A6,[1]ИТТ!$A:$H,5,FALSE),IFERROR(VLOOKUP($A6,[1]Schrack!$A:$H,5,FALSE),IFERROR(VLOOKUP($A6,'[1]LD GmbH'!$A:$H,5,FALSE),IFERROR(VLOOKUP($A6,[1]Крисметал!$A:$H,5,FALSE),IFERROR(VLOOKUP($A6,[1]Унител!$A:$H,5,FALSE),"")))))) -> 0 | F6: =IFERROR(VLOOKUP($A6,[1]Други!$A:$H,6,FALSE),IFERROR(VLOOKUP($A6,[1]ИТТ!$A:$H,6,FALSE),IFERROR(VLOOKUP($A6,[1]Schrack!$A:$H,6,FALSE),IFERROR(VLOOKUP($A6,'[1]LD GmbH'!$A:$H,6,FALSE),IFERROR(VLOOKUP($A6,[1]Крисметал!$A:$H,6,FALSE),IFERROR(VLOOKUP($A6,[1]Унител!$A:$H,6,FALSE),"")))))) -> 86.06265 | G6: =IFERROR(SUMIF(Модули!$A:$A,Себестойност!A6,Модули!$B:$B),"") -> 188 | H6: =IFERROR(F6*G6,"") -> 16179.778 | I6: =IFERROR(VLOOKUP($A6,[1]Други!$A:$H,8,FALSE),IFERROR(VLOOKUP($A6,[1]ИТТ!$A:$H,8,FALSE),IFERROR(VLOOKUP($A6,[1]Schrack!$A:$H,8,FALSE),IFERROR(VLOOKUP($A6,'[1]LD GmbH'!$A:$H,8,FALSE),IFERROR(VLOOKUP($A6,[1]Крисметал!$A:$H,8,FALSE),IFERROR(VLOOKUP($A6,[1]Унител!$A:$H,8,FALSE),"")))))) -> Suzhou VMA | J6: =IFERROR(VLOOKUP($A6,[1]Други!$A:$I,9,FALSE),IFERROR(VLOOKUP($A6,[1]ИТТ!$A:$I,9,FALSE),IFERROR(VLOOKUP($A6,[1]Schrack!$A:$I,9,FALSE),IFERROR(VLOOKUP($A6,'[1]LD GmbH'!$A:$I,9,FALSE),IFERROR(VLOOKUP($A6,[1]Крисметал!$A:$I,9,FALSE),IFERROR(VLOOKUP($A6,[1]Унител!$A:$I,9,FALSE),"")))))) -> 45473 | K6: =IFERROR(VLOOKUP($A6,[1]Други!$A:$H,7,FALSE),IFERROR(VLOOKUP($A6,[1]ИТТ!$A:$H,7,FALSE),IFERROR(VLOOKUP($A6,[1]Schrack!$A:$H,7,FALSE),IFERROR(VLOOKUP($A6,'[1]LD GmbH'!$A:$H,7,FALSE),IFERROR(VLOOKUP($A6,[1]Крисметал!$A:$H,7,FALSE),IFERROR(VLOOKUP($A6,[1]Унител!$A:$H,7,FALSE),"")))))) -> 103.27518 | L6: =G6*K6 -> 19415.734 | O6: =SUMIF(Модули!$A:$A,Себестойност!A6,Модули!$B:$B)-G6 -> 0
A7: Уплътнение от експандиран тефлон ф1060хф900х0,5 | B7: =IFERROR(VLOOKUP($A7,[1]Други!$A:$H,2,FALSE),IFERROR(VLOOKUP($A7,[1]ИТТ!$A:$H,2,FALSE),IFERROR(VLOOKUP($A7,[1]Schrack!$A:$H,2,FALSE),IFERROR(VLOOKUP($A7,'[1]LD GmbH'!$A:$H,2,FALSE),IFERROR(VLOOKUP($A7,[1]Крисметал!$A:$H,2,FALSE),IFERROR(VLOOKUP($A7,[1]Унител!$A:$H,2,FALSE),"")))))) -> - | C7: =IFERROR(VLOOKUP($A7,[1]Други!$A:$H,3,FALSE),IFERROR(VLOOKUP($A7,[1]ИТТ!$A:$H,3,FALSE),IFERROR(VLOOKUP($A7,[1]Schrack!$A:$H,3,FALSE),IFERROR(VLOOKUP($A7,'[1]LD GmbH'!$A:$H,3,FALSE),IFERROR(VLOOKUP($A7,[1]Крисметал!$A:$H,3,FALSE),IFERROR(VLOOKUP($A7,[1]Унител!$A:$H,3,FALSE),"")))))) -> 94.588998 | D7: =IFERROR(VLOOKUP($A7,[1]Други!$A:$H,4,FALSE),IFERROR(VLOOKUP($A7,[1]ИТТ!$A:$H,4,FALSE),IFERROR(VLOOKUP($A7,[1]Schrack!$A:$H,4,FALSE),IFERROR(VLOOKUP($A7,'[1]LD GmbH'!$A:$H,4,FALSE),IFERROR(VLOOKUP($A7,[1]Крисметал!$A:$H,4,FALSE),IFERROR(VLOOKUP($A7,[1]Унител!$A:$H,4,FALSE),"")))))) -> бр. | E7: =IFERROR(VLOOKUP($A7,[1]Други!$A:$H,5,FALSE),IFERROR(VLOOKUP($A7,[1]ИТТ!$A:$H,5,FALSE),IFERROR(VLOOKUP($A7,[1]Schrack!$A:$H,5,FALSE),IFERROR(VLOOKUP($A7,'[1]LD GmbH'!$A:$H,5,FALSE),IFERROR(VLOOKUP($A7,[1]Крисметал!$A:$H,5,FALSE),IFERROR(VLOOKUP($A7,[1]Унител!$A:$H,5,FALSE),"")))))) -> 0.39 | F7: =IFERROR(VLOOKUP($A7,[1]Други!$A:$H,6,FALSE),IFERROR(VLOOKUP($A7,[1]ИТТ!$A:$H,6,FALSE),IFERROR(VLOOKUP($A7,[1]Schrack!$A:$H,6,FALSE),IFERROR(VLOOKUP($A7,'[1]LD GmbH'!$A:$H,6,FALSE),IFERROR(VLOOKUP($A7,[1]Крисметал!$A:$H,6,FALSE),IFERROR(VLOOKUP($A7,[1]Унител!$A:$H,6,FALSE),"")))))) -> 57.699289 | G7: =IFERROR(SUMIF(Модули!$A:$A,Себестойност!A7,Модули!$B:$B),"") -> 282 | H7: =IFERROR(F7*G7,"") -> 16271.199 | I7: =IFERROR(VLOOKUP($A7,[1]Други!$A:$H,8,FALSE),IFERROR(VLOOKUP($A7,[1]ИТТ!$A:$H,8,FALSE),IFERROR(VLOOKUP($A7,[1]Schrack!$A:$H,8,FALSE),IFERROR(VLOOKUP($A7,'[1]LD GmbH'!$A:$H,8,FALSE),IFERROR(VLOOKUP($A7,[1]Крисметал!$A:$H,8,FALSE),IFERROR(VLOOKUP($A7,[1]Унител!$A:$H,8,FALSE),"")))))) -> ДЕАТРЕЙД | J7: =IFERROR(VLOOKUP($A7,[1]Други!$A:$I,9,FALSE),IFERROR(VLOOKUP($A7,[1]ИТТ!$A:$I,9,FALSE),IFERROR(VLOOKUP($A7,[1]Schrack!$A:$I,9,FALSE),IFERROR(VLOOKUP($A7,'[1]LD GmbH'!$A:$I,9,FALSE),IFERROR(VLOOKUP($A7,[1]Крисметал!$A:$I,9,FALSE),IFERROR(VLOOKUP($A7,[1]Унител!$A:$I,9,FALSE),"")))))) -> 45884 | K7: =IFERROR(VLOOKUP($A7,[1]Други!$A:$H,7,FALSE),IFERROR(VLOOKUP($A7,[1]ИТТ!$A:$H,7,FALSE),IFERROR(VLOOKUP($A7,[1]Schrack!$A:$H,7,FALSE),IFERROR(VLOOKUP($A7,'[1]LD GmbH'!$A:$H,7,FALSE),IFERROR(VLOOKUP($A7,[1]Крисметал!$A:$H,7,FALSE),IFERROR(VLOOKUP($A7,[1]Унител!$A:$H,7,FALSE),"")))))) -> 69.239147 | L7: =G7*K7 -> 19525.439 | O7: =SUMIF(Модули!$A:$A,Себестойност!A7,Модули!$B:$B)-G7 -> 0
A8: Гумен лист 5/1200мм EPDM/ | B8: =IFERROR(VLOOKUP($A8,[1]Други!$A:$H,2,FALSE),IFERROR(VLOOKUP($A8,[1]ИТТ!$A:$H,2,FALSE),IFERROR(VLOOKUP($A8,[1]Schrack!$A:$H,2,FALSE),IFERROR(VLOOKUP($A8,'[1]LD GmbH'!$A:$H,2,FALSE),IFERROR(VLOOKUP($A8,[1]Крисметал!$A:$H,2,FALSE),IFERROR(VLOOKUP($A8,[1]Унител!$A:$H,2,FALSE),"")))))) -> - | C8: =IFERROR(VLOOKUP($A8,[1]Други!$A:$H,3,FALSE),IFERROR(VLOOKUP($A8,[1]ИТТ!$A:$H,3,FALSE),IFERROR(VLOOKUP($A8,[1]Schrack!$A:$H,3,FALSE),IFERROR(VLOOKUP($A8,'[1]LD GmbH'!$A:$H,3,FALSE),IFERROR(VLOOKUP($A8,[1]Крисметал!$A:$H,3,FALSE),IFERROR(VLOOKUP($A8,[1]Унител!$A:$H,3,FALSE),"")))))) -> 43.45981 | D8: =IFERROR(VLOOKUP($A8,[1]Други!$A:$H,4,FALSE),IFERROR(VLOOKUP($A8,[1]ИТТ!$A:$H,4,FALSE),IFERROR(VLOOKUP($A8,[1]Schrack!$A:$H,4,FALSE),IFERROR(VLOOKUP($A8,'[1]LD GmbH'!$A:$H,4,FALSE),IFERROR(VLOOKUP($A8,[1]Крисметал!$A:$H,4,FALSE),IFERROR(VLOOKUP($A8,[1]Унител!$A:$H,4,FALSE),"")))))) -> кв.м. | E8: =IFERROR(VLOOKUP($A8,[1]Други!$A:$H,5,FALSE),IFERROR(VLOOKUP($A8,[1]ИТТ!$A:$H,5,FALSE),IFERROR(VLOOKUP($A8,[1]Schrack!$A:$H,5,FALSE),IFERROR(VLOOKUP($A8,'[1]LD GmbH'!$A:$H,5,FALSE),IFERROR(VLOOKUP($A8,[1]Крисметал!$A:$H,5,FALSE),IFERROR(VLOOKUP($A8,[1]Унител!$A:$H,5,FALSE),"")))))) -> 0 | F8: =IFERROR(VLOOKUP($A8,[1]Други!$A:$H,6,FALSE),IFERROR(VLOOKUP($A8,[1]ИТТ!$A:$H,6,FALSE),IFERROR(VLOOKUP($A8,[1]Schrack!$A:$H,6,FALSE),IFERROR(VLOOKUP($A8,'[1]LD GmbH'!$A:$H,6,FALSE),IFERROR(VLOOKUP($A8,[1]Крисметал!$A:$H,6,FALSE),IFERROR(VLOOKUP($A8,[1]Унител!$A:$H,6,FALSE),"")))))) -> 43.45981 | G8: =IFERROR(SUMIF(Модули!$A:$A,Себестойност!A8,Модули!$B:$B),"") -> 4.8 | H8: =IFERROR(F8*G8,"") -> 208.60709 | I8: =IFERROR(VLOOKUP($A8,[1]Други!$A:$H,8,FALSE),IFERROR(VLOOKUP($A8,[1]ИТТ!$A:$H,8,FALSE),IFERROR(VLOOKUP($A8,[1]Schrack!$A:$H,8,FALSE),IFERROR(VLOOKUP($A8,'[1]LD GmbH'!$A:$H,8,FALSE),IFERROR(VLOOKUP($A8,[1]Крисметал!$A:$H,8,FALSE),IFERROR(VLOOKUP($A8,[1]Унител!$A:$H,8,FALSE),"")))))) -> Микромакс трейд | J8: =IFERROR(VLOOKUP($A8,[1]Други!$A:$I,9,FALSE),IFERROR(VLOOKUP($A8,[1]ИТТ!$A:$I,9,FALSE),IFERROR(VLOOKUP($A8,[1]Schrack!$A:$I,9,FALSE),IFERROR(VLOOKUP($A8,'[1]LD GmbH'!$A:$I,9,FALSE),IFERROR(VLOOKUP($A8,[1]Крисметал!$A:$I,9,FALSE),IFERROR(VLOOKUP($A8,[1]Унител!$A:$I,9,FALSE),"")))))) -> 45628 | K8: =IFERROR(VLOOKUP($A8,[1]Други!$A:$H,7,FALSE),IFERROR(VLOOKUP($A8,[1]ИТТ!$A:$H,7,FALSE),IFERROR(VLOOKUP($A8,[1]Schrack!$A:$H,7,FALSE),IFERROR(VLOOKUP($A8,'[1]LD GmbH'!$A:$H,7,FALSE),IFERROR(VLOOKUP($A8,[1]Крисметал!$A:$H,7,FALSE),IFERROR(VLOOKUP($A8,[1]Унител!$A:$H,7,FALSE),"")))))) -> 52.151772 | L8: =G8*K8 -> 250.32851 | O8: =SUMIF(Модули!$A:$A,Себестойност!A8,Модули!$B:$B)-G8 -> 0
A9: Тефлонов лист 1000х1000х1 | B9: =IFERROR(VLOOKUP($A9,[1]Други!$A:$H,2,FALSE),IFERROR(VLOOKUP($A9,[1]ИТТ!$A:$H,2,FALSE),IFERROR(VLOOKUP($A9,[1]Schrack!$A:$H,2,FALSE),IFERROR(VLOOKUP($A9,'[1]LD GmbH'!$A:$H,2,FALSE),IFERROR(VLOOKUP($A9,[1]Крисметал!$A:$H,2,FALSE),IFERROR(VLOOKUP($A9,[1]Унител!$A:$H,2,FALSE),"")))))) -> SKU0000000427 | C9: =IFERROR(VLOOKUP($A9,[1]Други!$A:$H,3,FALSE),IFERROR(VLOOKUP($A9,[1]ИТТ!$A:$H,3,FALSE),IFERROR(VLOOKUP($A9,[1]Schrack!$A:$H,3,FALSE),IFERROR(VLOOKUP($A9,'[1]LD GmbH'!$A:$H,3,FALSE),IFERROR(VLOOKUP($A9,[1]Крисметал!$A:$H,3,FALSE),IFERROR(VLOOKUP($A9,[1]Унител!$A:$H,3,FALSE),"")))))) -> 57.56124 | D9: =IFERROR(VLOOKUP($A9,[1]Други!$A:$H,4,FALSE),IFERROR(VLOOKUP($A9,[1]ИТТ!$A:$H,4,FALSE),IFERROR(VLOOKUP($A9,[1]Schrack!$A:$H,4,FALSE),IFERROR(VLOOKUP($A9,'[1]LD GmbH'!$A:$H,4,FALSE),IFERROR(VLOOKUP($A9,[1]Крисметал!$A:$H,4,FALSE),IFERROR(VLOOKUP($A9,[1]Унител!$A:$H,4,FALSE),"")))))) -> бр. | E9: =IFERROR(VLOOKUP($A9,[1]Други!$A:$H,5,FALSE),IFERROR(VLOOKUP($A9,[1]ИТТ!$A:$H,5,FALSE),IFERROR(VLOOKUP($A9,[1]Schrack!$A:$H,5,FALSE),IFERROR(VLOOKUP($A9,'[1]LD GmbH'!$A:$H,5,FALSE),IFERROR(VLOOKUP($A9,[1]Крисметал!$A:$H,5,FALSE),IFERROR(VLOOKUP($A9,[1]Унител!$A:$H,5,FALSE),"")))))) -> 0 | F9: =IFERROR(VLOOKUP($A9,[1]Други!$A:$H,6,FALSE),IFERROR(VLOOKUP($A9,[1]ИТТ!$A:$H,6,FALSE),IFERROR(VLOOKUP($A9,[1]Schrack!$A:$H,6,FALSE),IFERROR(VLOOKUP($A9,'[1]LD GmbH'!$A:$H,6,FALSE),IFERROR(VLOOKUP($A9,[1]Крисметал!$A:$H,6,FALSE),IFERROR(VLOOKUP($A9,[1]Унител!$A:$H,6,FALSE),"")))))) -> 57.56124 | G9: =IFERROR(SUMIF(Модули!$A:$A,Себестойност!A9,Модули!$B:$B),"") -> 1 | H9: =IFERROR(F9*G9,"") -> 57.56124 | I9: =IFERROR(VLOOKUP($A9,[1]Други!$A:$H,8,FALSE),IFERROR(VLOOKUP($A9,[1]ИТТ!$A:$H,8,FALSE),IFERROR(VLOOKUP($A9,[1]Schrack!$A:$H,8,FALSE),IFERROR(VLOOKUP($A9,'[1]LD GmbH'!$A:$H,8,FALSE),IFERROR(VLOOKUP($A9,[1]Крисметал!$A:$H,8,FALSE),IFERROR(VLOOKUP($A9,[1]Унител!$A:$H,8,FALSE),"")))))) -> ДЕАТРЕЙД | J9: =IFERROR(VLOOKUP($A9,[1]Други!$A:$I,9,FALSE),IFERROR(VLOOKUP($A9,[1]ИТТ!$A:$I,9,FALSE),IFERROR(VLOOKUP($A9,[1]Schrack!$A:$I,9,FALSE),IFERROR(VLOOKUP($A9,'[1]LD GmbH'!$A:$I,9,FALSE),IFERROR(VLOOKUP($A9,[1]Крисметал!$A:$I,9,FALSE),IFERROR(VLOOKUP($A9,[1]Унител!$A:$I,9,FALSE),"")))))) -> 45707 | K9: =IFERROR(VLOOKUP($A9,[1]Други!$A:$H,7,FALSE),IFERROR(VLOOKUP($A9,[1]ИТТ!$A:$H,7,FALSE),IFERROR(VLOOKUP($A9,[1]Schrack!$A:$H,7,FALSE),IFERROR(VLOOKUP($A9,'[1]LD GmbH'!$A:$H,7,FALSE),IFERROR(VLOOKUP($A9,[1]Крисметал!$A:$H,7,FALSE),IFERROR(VLOOKUP($A9,[1]Унител!$A:$H,7,FALSE),"")))))) -> 69.073488 | L9: =G9*K9 -> 69.073488 | O9: =SUMIF(Модули!$A:$A,Себестойност!A9,Модули!$B:$B)-G9 -> 0
A10: Мембрани (Composite Membrane, 1*1m) (+транспорт) (+мито 6,5%) | B10: =IFERROR(VLOOKUP($A10,[1]Други!$A:$H,2,FALSE),IFERROR(VLOOKUP($A10,[1]ИТТ!$A:$H,2,FALSE),IFERROR(VLOOKUP($A10,[1]Schrack!$A:$H,2,FALSE),IFERROR(VLOOKUP($A10,'[1]LD GmbH'!$A:$H,2,FALSE),IFERROR(VLOOKUP($A10,[1]Крисметал!$A:$H,2,FALSE),IFERROR(VLOOKUP($A10,[1]Унител!$A:$H,2,FALSE),"")))))) -> - | C10: =IFERROR(VLOOKUP($A10,[1]Други!$A:$H,3,FALSE),IFERROR(VLOOKUP($A10,[1]ИТТ!$A:$H,3,FALSE),IFERROR(VLOOKUP($A10,[1]Schrack!$A:$H,3,FALSE),IFERROR(VLOOKUP($A10,'[1]LD GmbH'!$A:$H,3,FALSE),IFERROR(VLOOKUP($A10,[1]Крисметал!$A:$H,3,FALSE),IFERROR(VLOOKUP($A10,[1]Унител!$A:$H,3,FALSE),"")))))) -> 116.79855 | D10: =IFERROR(VLOOKUP($A10,[1]Други!$A:$H,4,FALSE),IFERROR(VLOOKUP($A10,[1]ИТТ!$A:$H,4,FALSE),IFERROR(VLOOKUP($A10,[1]Schrack!$A:$H,4,FALSE),IFERROR(VLOOKUP($A10,'[1]LD GmbH'!$A:$H,4,FALSE),IFERROR(VLOOKUP($A10,[1]Крисметал!$A:$H,4,FALSE),IFERROR(VLOOKUP($A10,[1]Унител!$A:$H,4,FALSE),"")))))) -> бр. | E10: =IFERROR(VLOOKUP($A10,[1]Други!$A:$H,5,FALSE),IFERROR(VLOOKUP($A10,[1]ИТТ!$A:$H,5,FALSE),IFERROR(VLOOKUP($A10,[1]Schrack!$A:$H,5,FALSE),IFERROR(VLOOKUP($A10,'[1]LD GmbH'!$A:$H,5,FALSE),IFERROR(VLOOKUP($A10,[1]Крисметал!$A:$H,5,FALSE),IFERROR(VLOOKUP($A10,[1]Унител!$A:$H,5,FALSE),"")))))) -> 0 | F10: =IFERROR(VLOOKUP($A10,[1]Други!$A:$H,6,FALSE),IFERROR(VLOOKUP($A10,[1]ИТТ!$A:$H,6,FALSE),IFERROR(VLOOKUP($A10,[1]Schrack!$A:$H,6,FALSE),IFERROR(VLOOKUP($A10,'[1]LD GmbH'!$A:$H,6,FALSE),IFERROR(VLOOKUP($A10,[1]Крисметал!$A:$H,6,FALSE),IFERROR(VLOOKUP($A10,[1]Унител!$A:$H,6,FALSE),"")))))) -> 116.79855 | G10: =IFERROR(SUMIF(Модули!$A:$A,Себестойност!A10,Модули!$B:$B),"") -> 90 | H10: =IFERROR(F10*G10,"") -> 10511.869 | I10: =IFERROR(VLOOKUP($A10,[1]Други!$A:$H,8,FALSE),IFERROR(VLOOKUP($A10,[1]ИТТ!$A:$H,8,FALSE),IFERROR(VLOOKUP($A10,[1]Schrack!$A:$H,8,FALSE),IFERROR(VLOOKUP($A10,'[1]LD GmbH'!$A:$H,8,FALSE),IFERROR(VLOOKUP($A10,[1]Крисметал!$A:$H,8,FALSE),IFERROR(VLOOKUP($A10,[1]Унител!$A:$H,8,FALSE),"")))))) -> Suzhou VMA | J10: =IFERROR(VLOOKUP($A10,[1]Други!$A:$I,9,FALSE),IFERROR(VLOOKUP($A10,[1]ИТТ!$A:$I,9,FALSE),IFERROR(VLOOKUP($A10,[1]Schrack!$A:$I,9,FALSE),IFERROR(VLOOKUP($A10,'[1]LD GmbH'!$A:$I,9,FALSE),IFERROR(VLOOKUP($A10,[1]Крисметал!$A:$I,9,FALSE),IFERROR(VLOOKUP($A10,[1]Унител!$A:$I,9,FALSE),"")))))) -> 45838 | K10: =IFERROR(VLOOKUP($A10,[1]Други!$A:$H,7,FALSE),IFERROR(VLOOKUP($A10,[1]ИТТ!$A:$H,7,FALSE),IFERROR(VLOOKUP($A10,[1]Schrack!$A:$H,7,FALSE),IFERROR(VLOOKUP($A10,'[1]LD GmbH'!$A:$H,7,FALSE),IFERROR(VLOOKUP($A10,[1]Крисметал!$A:$H,7,FALSE),IFERROR(VLOOKUP($A10,[1]Унител!$A:$H,7,FALSE),"")))))) -> 140.15826 | L10: =G10*K10 -> 12614.243 | O10: =SUMIF(Модули!$A:$A,Себестойност!A10,Модули!$B:$B)-G10 -> 0
A11: Перфорирана ламарина LB 1000x2000x0,5; RV 2-3: 1.4404 | B11: =IFERROR(VLOOKUP($A11,[1]Други!$A:$H,2,FALSE),IFERROR(VLOOKUP($A11,[1]ИТТ!$A:$H,2,FALSE),IFERROR(VLOOKUP($A11,[1]Schrack!$A:$H,2,FALSE),IFERROR(VLOOKUP($A11,'[1]LD GmbH'!$A:$H,2,FALSE),IFERROR(VLOOKUP($A11,[1]Крисметал!$A:$H,2,FALSE),IFERROR(VLOOKUP($A11,[1]Унител!$A:$H,2,FALSE),"")))))) -> 00721431 | C11: =IFERROR(VLOOKUP($A11,[1]Други!$A:$H,3,FALSE),IFERROR(VLOOKUP($A11,[1]ИТТ!$A:$H,3,FALSE),IFERROR(VLOOKUP($A11,[1]Schrack!$A:$H,3,FALSE),IFERROR(VLOOKUP($A11,'[1]LD GmbH'!$A:$H,3,FALSE),IFERROR(VLOOKUP($A11,[1]Крисметал!$A:$H,3,FALSE),IFERROR(VLOOKUP($A11,[1]Унител!$A:$H,3,FALSE),"")))))) -> 60.122812 | D11: =IFERROR(VLOOKUP($A11,[1]Други!$A:$H,4,FALSE),IFERROR(VLOOKUP($A11,[1]ИТТ!$A:$H,4,FALSE),IFERROR(VLOOKUP($A11,[1]Schrack!$A:$H,4,FALSE),IFERROR(VLOOKUP($A11,'[1]LD GmbH'!$A:$H,4,FALSE),IFERROR(VLOOKUP($A11,[1]Крисметал!$A:$H,4,FALSE),IFERROR(VLOOKUP($A11,[1]Унител!$A:$H,4,FALSE),"")))))) -> лист | E11: =IFERROR(VLOOKUP($A11,[1]Други!$A:$H,5,FALSE),IFERROR(VLOOKUP($A11,[1]ИТТ!$A:$H,5,FALSE),IFERROR(VLOOKUP($A11,[1]Schrack!$A:$H,5,FALSE),IFERROR(VLOOKUP($A11,'[1]LD GmbH'!$A:$H,5,FALSE),IFERROR(VLOOKUP($A11,[1]Крисметал!$A:$H,5,FALSE),IFERROR(VLOOKUP($A11,[1]Унител!$A:$H,5,FALSE),"")))))) -> 0 | F11: =IFERROR(VLOOKUP($A11,[1]Други!$A:$H,6,FALSE),IFERROR(VLOOKUP($A11,[1]ИТТ!$A:$H,6,FALSE),IFERROR(VLOOKUP($A11,[1]Schrack!$A:$H,6,FALSE),IFERROR(VLOOKUP($A11,'[1]LD GmbH'!$A:$H,6,FALSE),IFERROR(VLOOKUP($A11,[1]Крисметал!$A:$H,6,FALSE),IFERROR(VLOOKUP($A11,[1]Унител!$A:$H,6,FALSE),"")))))) -> 60.122812 | G11: =IFERROR(SUMIF(Модули!$A:$A,Себестойност!A11,Модули!$B:$B),"") -> 90 | H11: =IFERROR(F11*G11,"") -> 5411.0531 | I11: =IFERROR(VLOOKUP($A11,[1]Други!$A:$H,8,FALSE),IFERROR(VLOOKUP($A11,[1]ИТТ!$A:$H,8,FALSE),IFERROR(VLOOKUP($A11,[1]Schrack!$A:$H,8,FALSE),IFERROR(VLOOKUP($A11,'[1]LD GmbH'!$A:$H,8,FALSE),IFERROR(VLOOKUP($A11,[1]Крисметал!$A:$H,8,FALSE),IFERROR(VLOOKUP($A11,[1]Унител!$A:$H,8,FALSE),"")))))) -> ДФ България | J11: =IFERROR(VLOOKUP($A11,[1]Други!$A:$I,9,FALSE),IFERROR(VLOOKUP($A11,[1]ИТТ!$A:$I,9,FALSE),IFERROR(VLOOKUP($A11,[1]Schrack!$A:$I,9,FALSE),IFERROR(VLOOKUP($A11,'[1]LD GmbH'!$A:$I,9,FALSE),IFERROR(VLOOKUP($A11,[1]Крисметал!$A:$I,9,FALSE),IFERROR(VLOOKUP($A11,[1]Унител!$A:$I,9,FALSE),"")))))) -> 45887 | K11: =IFERROR(VLOOKUP($A11,[1]Други!$A:$H,7,FALSE),IFERROR(VLOOKUP($A11,[1]ИТТ!$A:$H,7,FALSE),IFERROR(VLOOKUP($A11,[1]Schrack!$A:$H,7,FALSE),IFERROR(VLOOKUP($A11,'[1]LD GmbH'!$A:$H,7,FALSE),IFERROR(VLOOKUP($A11,[1]Крисметал!$A:$H,7,FALSE),IFERROR(VLOOKUP($A11,[1]Унител!$A:$H,7,FALSE),"")))))) -> 72.147375 | L11: =G11*K11 -> 6493.2637 | O11: =SUMIF(Модули!$A:$A,Себестойност!A11,Модули!$B:$B)-G11 -> 0
A12: Плетена мрежа INOX AISI 316L H 1000 mm (+ транспорт) | B12: =IFERROR(VLOOKUP($A12,[1]Други!$A:$H,2,FALSE),IFERROR(VLOOKUP($A12,[1]ИТТ!$A:$H,2,FALSE),IFERROR(VLOOKUP($A12,[1]Schrack!$A:$H,2,FALSE),IFERROR(VLOOKUP($A12,'[1]LD GmbH'!$A:$H,2,FALSE),IFERROR(VLOOKUP($A12,[1]Крисметал!$A:$H,2,FALSE),IFERROR(VLOOKUP($A12,[1]Унител!$A:$H,2,FALSE),"")))))) -> 02112004 | C12: =IFERROR(VLOOKUP($A12,[1]Други!$A:$H,3,FALSE),IFERROR(VLOOKUP($A12,[1]ИТТ!$A:$H,3,FALSE),IFERROR(VLOOKUP($A12,[1]Schrack!$A:$H,3,FALSE),IFERROR(VLOOKUP($A12,'[1]LD GmbH'!$A:$H,3,FALSE),IFERROR(VLOOKUP($A12,[1]Крисметал!$A:$H,3,FALSE),IFERROR(VLOOKUP($A12,[1]Унител!$A:$H,3,FALSE),"")))))) -> 12.67 | D12: =IFERROR(VLOOKUP($A12,[1]Други!$A:$H,4,FALSE),IFERROR(VLOOKUP($A12,[1]ИТТ!$A:$H,4,FALSE),IFERROR(VLOOKUP($A12,[1]Schrack!$A:$H,4,FALSE),IFERROR(VLOOKUP($A12,'[1]LD GmbH'!$A:$H,4,FALSE),IFERROR(VLOOKUP($A12,[1]Крисметал!$A:$H,4,FALSE),IFERROR(VLOOKUP($A12,[1]Унител!$A:$H,4,FALSE),"")))))) -> кг. | E12: =IFERROR(VLOOKUP($A12,[1]Други!$A:$H,5,FALSE),IFERROR(VLOOKUP($A12,[1]ИТТ!$A:$H,5,FALSE),IFERROR(VLOOKUP($A12,[1]Schrack!$A:$H,5,FALSE),IFERROR(VLOOKUP($A12,'[1]LD GmbH'!$A:$H,5,FALSE),IFERROR(VLOOKUP($A12,[1]Крисметал!$A:$H,5,FALSE),IFERROR(VLOOKUP($A12,[1]Унител!$A:$H,5,FALSE),"")))))) -> 0 | F12: =IFERROR(VLOOKUP($A12,[1]Други!$A:$H,6,FALSE),IFERROR(VLOOKUP($A12,[1]ИТТ!$A:$H,6,FALSE),IFERROR(VLOOKUP($A12,[1]Schrack!$A:$H,6,FALSE),IFERROR(VLOOKUP($A12,'[1]LD GmbH'!$A:$H,6,FALSE),IFERROR(VLOOKUP($A12,[1]Крисметал!$A:$H,6,FALSE),IFERROR(VLOOKUP($A12,[1]Унител!$A:$H,6,FALSE),"")))))) -> 12.67 | G12: =IFERROR(SUMIF(Модули!$A:$A,Себестойност!A12,Модули!$B:$B),"") -> 92.24 | H12: =IFERROR(F12*G12,"") -> 1168.6808 | I12: =IFERROR(VLOOKUP($A12,[1]Други!$A:$H,8,FALSE),IFERROR(VLOOKUP($A12,[1]ИТТ!$A:$H,8,FALSE),IFERROR(VLOOKUP($A12,[1]Schrack!$A:$H,8,FALSE),IFERROR(VLOOKUP($A12,'[1]LD GmbH'!$A:$H,8,FALSE),IFERROR(VLOOKUP($A12,[1]Крисметал!$A:$H,8,FALSE),IFERROR(VLOOKUP($A12,[1]Унител!$A:$H,8,FALSE),"")))))) -> SOTAR S.R.L | J12: =IFERROR(VLOOKUP($A12,[1]Други!$A:$I,9,FALSE),IFERROR(VLOOKUP($A12,[1]ИТТ!$A:$I,9,FALSE),IFERROR(VLOOKUP($A12,[1]Schrack!$A:$I,9,FALSE),IFERROR(VLOOKUP($A12,'[1]LD GmbH'!$A:$I,9,FALSE),IFERROR(VLOOKUP($A12,[1]Крисметал!$A:$I,9,FALSE),IFERROR(VLOOKUP($A12,[1]Унител!$A:$I,9,FALSE),"")))))) -> 45678 | K12: =IFERROR(VLOOKUP($A12,[1]Други!$A:$H,7,FALSE),IFERROR(VLOOKUP($A12,[1]ИТТ!$A:$H,7,FALSE),IFERROR(VLOOKUP($A12,[1]Schrack!$A:$H,7,FALSE),IFERROR(VLOOKUP($A12,'[1]LD GmbH'!$A:$H,7,FALSE),IFERROR(VLOOKUP($A12,[1]Крисметал!$A:$H,7,FALSE),IFERROR(VLOOKUP($A12,[1]Унител!$A:$H,7,FALSE),"")))))) -> 12.67 | L12: =G12*K12 -> 1168.6808 | O12: =SUMIF(Модули!$A:$A,Себестойност!A12,Модули!$B:$B)-G12 -> 0
A13: КРЕПЕЖИ
A14: Ринг гайка, DIN 582, C15, vZn, M 24 | B14: =IFERROR(VLOOKUP($A14,[1]Други!$A:$H,2,FALSE),IFERROR(VLOOKUP($A14,[1]ИТТ!$A:$H,2,FALSE),IFERROR(VLOOKUP($A14,[1]Schrack!$A:$H,2,FALSE),IFERROR(VLOOKUP($A14,'[1]LD GmbH'!$A:$H,2,FALSE),IFERROR(VLOOKUP($A14,[1]Крисметал!$A:$H,2,FALSE),IFERROR(VLOOKUP($A14,[1]Унител!$A:$H,2,FALSE),"")))))) -> 00582 0001 24 | C14: =IFERROR(VLOOKUP($A14,[1]Други!$A:$H,3,FALSE),IFERROR(VLOOKUP($A14,[1]ИТТ!$A:$H,3,FALSE),IFERROR(VLOOKUP($A14,[1]Schrack!$A:$H,3,FALSE),IFERROR(VLOOKUP($A14,'[1]LD GmbH'!$A:$H,3,FALSE),IFERROR(VLOOKUP($A14,[1]Крисметал!$A:$H,3,FALSE),IFERROR(VLOOKUP($A14,[1]Унител!$A:$H,3,FALSE),"")))))) -> 437.15456 | D14: =IFERROR(VLOOKUP($A14,[1]Други!$A:$H,4,FALSE),IFERROR(VLOOKUP($A14,[1]ИТТ!$A:$H,4,FALSE),IFERROR(VLOOKUP($A14,[1]Schrack!$A:$H,4,FALSE),IFERROR(VLOOKUP($A14,'[1]LD GmbH'!$A:$H,4,FALSE),IFERROR(VLOOKUP($A14,[1]Крисметал!$A:$H,4,FALSE),IFERROR(VLOOKUP($A14,[1]Унител!$A:$H,4,FALSE),"")))))) -> 100 бр. | E14: =IFERROR(VLOOKUP($A14,[1]Други!$A:$H,5,FALSE),IFERROR(VLOOKUP($A14,[1]ИТТ!$A:$H,5,FALSE),IFERROR(VLOOKUP($A14,[1]Schrack!$A:$H,5,FALSE),IFERROR(VLOOKUP($A14,'[1]LD GmbH'!$A:$H,5,FALSE),IFERROR(VLOOKUP($A14,[1]Крисметал!$A:$H,5,FALSE),IFERROR(VLOOKUP($A14,[1]Унител!$A:$H,5,FALSE),"")))))) -> 0 | F14: =IFERROR(VLOOKUP($A14,[1]Други!$A:$H,6,FALSE),IFERROR(VLOOKUP($A14,[1]ИТТ!$A:$H,6,FALSE),IFERROR(VLOOKUP($A14,[1]Schrack!$A:$H,6,FALSE),IFERROR(VLOOKUP($A14,'[1]LD GmbH'!$A:$H,6,FALSE),IFERROR(VLOOKUP($A14,[1]Крисметал!$A:$H,6,FALSE),IFERROR(VLOOKUP($A14,[1]Унител!$A:$H,6,FALSE),"")))))) -> 437.15456 | G14: =IFERROR(SUMIF(Модули!$A:$A,Себестойност!A14,Модули!$B:$B),"") -> 0.06 | H14: =IFERROR(F14*G14,"") -> 26.229274 | I14: =IFERROR(VLOOKUP($A14,[1]Други!$A:$H,8,FALSE),IFERROR(VLOOKUP($A14,[1]ИТТ!$A:$H,8,FALSE),IFERROR(VLOOKUP($A14,[1]Schrack!$A:$H,8,FALSE),IFERROR(VLOOKUP($A14,'[1]LD GmbH'!$A:$H,8,FALSE),IFERROR(VLOOKUP($A14,[1]Крисметал!$A:$H,8,FALSE),IFERROR(VLOOKUP($A14,[1]Унител!$A:$H,8,FALSE),"")))))) -> ИТТ | J14: =IFERROR(VLOOKUP($A14,[1]Други!$A:$I,9,FALSE),IFERROR(VLOOKUP($A14,[1]ИТТ!$A:$I,9,FALSE),IFERROR(VLOOKUP($A14,[1]Schrack!$A:$I,9,FALSE),IFERROR(VLOOKUP($A14,'[1]LD GmbH'!$A:$I,9,FALSE),IFERROR(VLOOKUP($A14,[1]Крисметал!$A:$I,9,FALSE),IFERROR(VLOOKUP($A14,[1]Унител!$A:$I,9,FALSE),"")))))) -> 45693 | K14: =IFERROR(VLOOKUP($A14,[1]Други!$A:$H,7,FALSE),IFERROR(VLOOKUP($A14,[1]ИТТ!$A:$H,7,FALSE),IFERROR(VLOOKUP($A14,[1]Schrack!$A:$H,7,FALSE),IFERROR(VLOOKUP($A14,'[1]LD GmbH'!$A:$H,7,FALSE),IFERROR(VLOOKUP($A14,[1]Крисметал!$A:$H,7,FALSE),IFERROR(VLOOKUP($A14,[1]Унител!$A:$H,7,FALSE),"")))))) -> 524.58547 | L14: =G14*K14 -> 31.475128 | O14: =SUMIF(Модули!$A:$A,Себестойност!A14,Модули!$B:$B)-G14 -> 0
A15: Шпилка М56х4, 8.8, черна L=2000mm | B15: =IFERROR(VLOOKUP($A15,[1]Други!$A:$H,2,FALSE),IFERROR(VLOOKUP($A15,[1]ИТТ!$A:$H,2,FALSE),IFERROR(VLOOKUP($A15,[1]Schrack!$A:$H,2,FALSE),IFERROR(VLOOKUP($A15,'[1]LD GmbH'!$A:$H,2,FALSE),IFERROR(VLOOKUP($A15,[1]Крисметал!$A:$H,2,FALSE),IFERROR(VLOOKUP($A15,[1]Унител!$A:$H,2,FALSE),"")))))) -> - | C15: =IFERROR(VLOOKUP($A15,[1]Други!$A:$H,3,FALSE),IFERROR(VLOOKUP($A15,[1]ИТТ!$A:$H,3,FALSE),IFERROR(VLOOKUP($A15,[1]Schrack!$A:$H,3,FALSE),IFERROR(VLOOKUP($A15,'[1]LD GmbH'!$A:$H,3,FALSE),IFERROR(VLOOKUP($A15,[1]Крисметал!$A:$H,3,FALSE),IFERROR(VLOOKUP($A15,[1]Унител!$A:$H,3,FALSE),"")))))) -> 176.90699 | D15: =IFERROR(VLOOKUP($A15,[1]Други!$A:$H,4,FALSE),IFERROR(VLOOKUP($A15,[1]ИТТ!$A:$H,4,FALSE),IFERROR(VLOOKUP($A15,[1]Schrack!$A:$H,4,FALSE),IFERROR(VLOOKUP($A15,'[1]LD GmbH'!$A:$H,4,FALSE),IFERROR(VLOOKUP($A15,[1]Крисметал!$A:$H,4,FALSE),IFERROR(VLOOKUP($A15,[1]Унител!$A:$H,4,FALSE),"")))))) -> бр. | E15: =IFERROR(VLOOKUP($A15,[1]Други!$A:$H,5,FALSE),IFERROR(VLOOKUP($A15,[1]ИТТ!$A:$H,5,FALSE),IFERROR(VLOOKUP($A15,[1]Schrack!$A:$H,5,FALSE),IFERROR(VLOOKUP($A15,'[1]LD GmbH'!$A:$H,5,FALSE),IFERROR(VLOOKUP($A15,[1]Крисметал!$A:$H,5,FALSE),IFERROR(VLOOKUP($A15,[1]Унител!$A:$H,5,FALSE),"")))))) -> 0 | F15: =IFERROR(VLOOKUP($A15,[1]Други!$A:$H,6,FALSE),IFERROR(VLOOKUP($A15,[1]ИТТ!$A:$H,6,FALSE),IFERROR(VLOOKUP($A15,[1]Schrack!$A:$H,6,FALSE),IFERROR(VLOOKUP($A15,'[1]LD GmbH'!$A:$H,6,FALSE),IFERROR(VLOOKUP($A15,[1]Крисметал!$A:$H,6,FALSE),IFERROR(VLOOKUP($A15,[1]Унител!$A:$H,6,FALSE),"")))))) -> 176.90699 | G15: =IFERROR(SUMIF(Модули!$A:$A,Себестойност!A15,Модули!$B:$B),"") -> 10 | H15: =IFERROR(F15*G15,"") -> 1769.0699 | I15: =IFERROR(VLOOKUP($A15,[1]Други!$A:$H,8,FALSE),IFERROR(VLOOKUP($A15,[1]ИТТ!$A:$H,8,FALSE),IFERROR(VLOOKUP($A15,[1]Schrack!$A:$H,8,FALSE),IFERROR(VLOOKUP($A15,'[1]LD GmbH'!$A:$H,8,FALSE),IFERROR(VLOOKUP($A15,[1]Крисметал!$A:$H,8,FALSE),IFERROR(VLOOKUP($A15,[1]Унител!$A:$H,8,FALSE),"")))))) -> Аронов 87 | J15: =IFERROR(VLOOKUP($A15,[1]Други!$A:$I,9,FALSE),IFERROR(VLOOKUP($A15,[1]ИТТ!$A:$I,9,FALSE),IFERROR(VLOOKUP($A15,[1]Schrack!$A:$I,9,FALSE),IFERROR(VLOOKUP($A15,'[1]LD GmbH'!$A:$I,9,FALSE),IFERROR(VLOOKUP($A15,[1]Крисметал!$A:$I,9,FALSE),IFERROR(VLOOKUP($A15,[1]Унител!$A:$I,9,FALSE),"")))))) -> 45565 | K15: =IFERROR(VLOOKUP($A15,[1]Други!$A:$H,7,FALSE),IFERROR(VLOOKUP($A15,[1]ИТТ!$A:$H,7,FALSE),IFERROR(VLOOKUP($A15,[1]Schrack!$A:$H,7,FALSE),IFERROR(VLOOKUP($A15,'[1]LD GmbH'!$A:$H,7,FALSE),IFERROR(VLOOKUP($A15,[1]Крисметал!$A:$H,7,FALSE),IFERROR(VLOOKUP($A15,[1]Унител!$A:$H,7,FALSE),"")))))) -> 212.28839 | L15: =G15*K15 -> 2122.8839 | O15: =SUMIF(Модули!$A:$A,Себестойност!A15,Модули!$B:$B)-G15 -> 0
A16: Гайка M56x4, 8.8 | B16: =IFERROR(VLOOKUP($A16,[1]Други!$A:$H,2,FALSE),IFERROR(VLOOKUP($A16,[1]ИТТ!$A:$H,2,FALSE),IFERROR(VLOOKUP($A16,[1]Schrack!$A:$H,2,FALSE),IFERROR(VLOOKUP($A16,'[1]LD GmbH'!$A:$H,2,FALSE),IFERROR(VLOOKUP($A16,[1]Крисметал!$A:$H,2,FALSE),IFERROR(VLOOKUP($A16,[1]Унител!$A:$H,2,FALSE),"")))))) -> - | C16: =IFERROR(VLOOKUP($A16,[1]Други!$A:$H,3,FALSE),IFERROR(VLOOKUP($A16,[1]ИТТ!$A:$H,3,FALSE),IFERROR(VLOOKUP($A16,[1]Schrack!$A:$H,3,FALSE),IFERROR(VLOOKUP($A16,'[1]LD GmbH'!$A:$H,3,FALSE),IFERROR(VLOOKUP($A16,[1]Крисметал!$A:$H,3,FALSE),IFERROR(VLOOKUP($A16,[1]Унител!$A:$H,3,FALSE),"")))))) -> 16.616986 | D16: =IFERROR(VLOOKUP($A16,[1]Други!$A:$H,4,FALSE),IFERROR(VLOOKUP($A16,[1]ИТТ!$A:$H,4,FALSE),IFERROR(VLOOKUP($A16,[1]Schrack!$A:$H,4,FALSE),IFERROR(VLOOKUP($A16,'[1]LD GmbH'!$A:$H,4,FALSE),IFERROR(VLOOKUP($A16,[1]Крисметал!$A:$H,4,FALSE),IFERROR(VLOOKUP($A16,[1]Унител!$A:$H,4,FALSE),"")))))) -> бр. | E16: =IFERROR(VLOOKUP($A16,[1]Други!$A:$H,5,FALSE),IFERROR(VLOOKUP($A16,[1]ИТТ!$A:$H,5,FALSE),IFERROR(VLOOKUP($A16,[1]Schrack!$A:$H,5,FALSE),IFERROR(VLOOKUP($A16,'[1]LD GmbH'!$A:$H,5,FALSE),IFERROR(VLOOKUP($A16,[1]Крисметал!$A:$H,5,FALSE),IFERROR(VLOOKUP($A16,[1]Унител!$A:$H,5,FALSE),"")))))) -> 0 | F16: =IFERROR(VLOOKUP($A16,[1]Други!$A:$H,6,FALSE),IFERROR(VLOOKUP($A16,[1]ИТТ!$A:$H,6,FALSE),IFERROR(VLOOKUP($A16,[1]Schrack!$A:$H,6,FALSE),IFERROR(VLOOKUP($A16,'[1]LD GmbH'!$A:$H,6,FALSE),IFERROR(VLOOKUP($A16,[1]Крисметал!$A:$H,6,FALSE),IFERROR(VLOOKUP($A16,[1]Унител!$A:$H,6,FALSE),"")))))) -> 16.616986 | G16: =IFERROR(SUMIF(Модули!$A:$A,Себестойност!A16,Модули!$B:$B),"") -> 20 | H16: =IFERROR(F16*G16,"") -> 332.33972 | I16: =IFERROR(VLOOKUP($A16,[1]Други!$A:$H,8,FALSE),IFERROR(VLOOKUP($A16,[1]ИТТ!$A:$H,8,FALSE),IFERROR(VLOOKUP($A16,[1]Schrack!$A:$H,8,FALSE),IFERROR(VLOOKUP($A16,'[1]LD GmbH'!$A:$H,8,FALSE),IFERROR(VLOOKUP($A16,[1]Крисметал!$A:$H,8,FALSE),IFERROR(VLOOKUP($A16,[1]Унител!$A:$H,8,FALSE),"")))))) -> Аронов 87 | J16: =IFERROR(VLOOKUP($A16,[1]Други!$A:$I,9,FALSE),IFERROR(VLOOKUP($A16,[1]ИТТ!$A:$I,9,FALSE),IFERROR(VLOOKUP($A16,[1]Schrack!$A:$I,9,FALSE),IFERROR(VLOOKUP($A16,'[1]LD GmbH'!$A:$I,9,FALSE),IFERROR(VLOOKUP($A16,[1]Крисметал!$A:$I,9,FALSE),IFERROR(VLOOKUP($A16,[1]Унител!$A:$I,9,FALSE),"")))))) -> 45575 | K16: =IFERROR(VLOOKUP($A16,[1]Други!$A:$H,7,FALSE),IFERROR(VLOOKUP($A16,[1]ИТТ!$A:$H,7,FALSE),IFERROR(VLOOKUP($A16,[1]Schrack!$A:$H,7,FALSE),IFERROR(VLOOKUP($A16,'[1]LD GmbH'!$A:$H,7,FALSE),IFERROR(VLOOKUP($A16,[1]Крисметал!$A:$H,7,FALSE),IFERROR(VLOOKUP($A16,[1]Унител!$A:$H,7,FALSE),"")))))) -> 19.940383 | L16: =G16*K16 -> 398.80767 | O16: =SUMIF(Модули!$A:$A,Себестойност!A16,Модули!$B:$B)-G16 -> 0
A17: Шайба подложна, DIN 125A, vZn, M56 | B17: =IFERROR(VLOOKUP($A17,[1]Други!$A:$H,2,FALSE),IFERROR(VLOOKUP($A17,[1]ИТТ!$A:$H,2,FALSE),IFERROR(VLOOKUP($A17,[1]Schrack!$A:$H,2,FALSE),IFERROR(VLOOKUP($A17,'[1]LD GmbH'!$A:$H,2,FALSE),IFERROR(VLOOKUP($A17,[1]Крисметал!$A:$H,2,FALSE),IFERROR(VLOOKUP($A17,[1]Унител!$A:$H,2,FALSE),"")))))) -> 00125 0001 56 | C17: =IFERROR(VLOOKUP($A17,[1]Други!$A:$H,3,FALSE),IFERROR(VLOOKUP($A17,[1]ИТТ!$A:$H,3,FALSE),IFERROR(VLOOKUP($A17,[1]Schrack!$A:$H,3,FALSE),IFERROR(VLOOKUP($A17,'[1]LD GmbH'!$A:$H,3,FALSE),IFERROR(VLOOKUP($A17,[1]Крисметал!$A:$H,3,FALSE),IFERROR(VLOOKUP($A17,[1]Унител!$A:$H,3,FALSE),"")))))) -> 170.43915 | D17: =IFERROR(VLOOKUP($A17,[1]Други!$A:$H,4,FALSE),IFERROR(VLOOKUP($A17,[1]ИТТ!$A:$H,4,FALSE),IFERROR(VLOOKUP($A17,[1]Schrack!$A:$H,4,FALSE),IFERROR(VLOOKUP($A17,'[1]LD GmbH'!$A:$H,4,FALSE),IFERROR(VLOOKUP($A17,[1]Крисметал!$A:$H,4,FALSE),IFERROR(VLOOKUP($A17,[1]Унител!$A:$H,4,FALSE),"")))))) -> 100 бр. | E17: =IFERROR(VLOOKUP($A17,[1]Други!$A:$H,5,FALSE),IFERROR(VLOOKUP($A17,[1]ИТТ!$A:$H,5,FALSE),IFERROR(VLOOKUP($A17,[1]Schrack!$A:$H,5,FALSE),IFERROR(VLOOKUP($A17,'[1]LD GmbH'!$A:$H,5,FALSE),IFERROR(VLOOKUP($A17,[1]Крисметал!$A:$H,5,FALSE),IFERROR(VLOOKUP($A17,[1]Унител!$A:$H,5,FALSE),"")))))) -> 0 | F17: =IFERROR(VLOOKUP($A17,[1]Други!$A:$H,6,FALSE),IFERROR(VLOOKUP($A17,[1]ИТТ!$A:$H,6,FALSE),IFERROR(VLOOKUP($A17,[1]Schrack!$A:$H,6,FALSE),IFERROR(VLOOKUP($A17,'[1]LD GmbH'!$A:$H,6,FALSE),IFERROR(VLOOKUP($A17,[1]Крисметал!$A:$H,6,FALSE),IFERROR(VLOOKUP($A17,[1]Унител!$A:$H,6,FALSE),"")))))) -> 170.43915 | G17: =IFERROR(SUMIF(Модули!$A:$A,Себестойност!A17,Модули!$B:$B),"") -> 0.1 | H17: =IFERROR(F17*G17,"") -> 17.043915 | I17: =IFERROR(VLOOKUP($A17,[1]Други!$A:$H,8,FALSE),IFERROR(VLOOKUP($A17,[1]ИТТ!$A:$H,8,FALSE),IFERROR(VLOOKUP($A17,[1]Schrack!$A:$H,8,FALSE),IFERROR(VLOOKUP($A17,'[1]LD GmbH'!$A:$H,8,FALSE),IFERROR(VLOOKUP($A17,[1]Крисметал!$A:$H,8,FALSE),IFERROR(VLOOKUP($A17,[1]Унител!$A:$H,8,FALSE),"")))))) -> ИТТ | J17: =IFERROR(VLOOKUP($A17,[1]Други!$A:$I,9,FALSE),IFERROR(VLOOKUP($A17,[1]ИТТ!$A:$I,9,FALSE),IFERROR(VLOOKUP($A17,[1]Schrack!$A:$I,9,FALSE),IFERROR(VLOOKUP($A17,'[1]LD GmbH'!$A:$I,9,FALSE),IFERROR(VLOOKUP($A17,[1]Крисметал!$A:$I,9,FALSE),IFERROR(VLOOKUP($A17,[1]Унител!$A:$I,9,FALSE),"")))))) -> 45408 | K17: =IFERROR(VLOOKUP($A17,[1]Други!$A:$H,7,FALSE),IFERROR(VLOOKUP($A17,[1]ИТТ!$A:$H,7,FALSE),IFERROR(VLOOKUP($A17,[1]Schrack!$A:$H,7,FALSE),IFERROR(VLOOKUP($A17,'[1]LD GmbH'!$A:$H,7,FALSE),IFERROR(VLOOKUP($A17,[1]Крисметал!$A:$H,7,FALSE),IFERROR(VLOOKUP($A17,[1]Унител!$A:$H,7,FALSE),"")))))) -> 204.52698 | L17: =G17*K17 -> 20.452698 | O17: =SUMIF(Модули!$A:$A,Себестойност!A17,Модули!$B:$B)-G17 -> 0
A18: Disc Spring 112х57х4mm (+транспорт) (+мито 6,5%) | B18: =IFERROR(VLOOKUP($A18,[1]Други!$A:$H,2,FALSE),IFERROR(VLOOKUP($A18,[1]ИТТ!$A:$H,2,FALSE),IFERROR(VLOOKUP($A18,[1]Schrack!$A:$H,2,FALSE),IFERROR(VLOOKUP($A18,'[1]LD GmbH'!$A:$H,2,FALSE),IFERROR(VLOOKUP($A18,[1]Крисметал!$A:$H,2,FALSE),IFERROR(VLOOKUP($A18,[1]Унител!$A:$H,2,FALSE),"")))))) -> - | C18: =IFERROR(VLOOKUP($A18,[1]Други!$A:$H,3,FALSE),IFERROR(VLOOKUP($A18,[1]ИТТ!$A:$H,3,FALSE),IFERROR(VLOOKUP($A18,[1]Schrack!$A:$H,3,FALSE),IFERROR(VLOOKUP($A18,'[1]LD GmbH'!$A:$H,3,FALSE),IFERROR(VLOOKUP($A18,[1]Крисметал!$A:$H,3,FALSE),IFERROR(VLOOKUP($A18,[1]Унител!$A:$H,3,FALSE),"")))))) -> 4.07895 | D18: =IFERROR(VLOOKUP($A18,[1]Други!$A:$H,4,FALSE),IFERROR(VLOOKUP($A18,[1]ИТТ!$A:$H,4,FALSE),IFERROR(VLOOKUP($A18,[1]Schrack!$A:$H,4,FALSE),IFERROR(VLOOKUP($A18,'[1]LD GmbH'!$A:$H,4,FALSE),IFERROR(VLOOKUP($A18,[1]Крисметал!$A:$H,4,FALSE),IFERROR(VLOOKUP($A18,[1]Унител!$A:$H,4,FALSE),"")))))) -> бр. | E18: =IFERROR(VLOOKUP($A18,[1]Други!$A:$H,5,FALSE),IFERROR(VLOOKUP($A18,[1]ИТТ!$A:$H,5,FALSE),IFERROR(VLOOKUP($A18,[1]Schrack!$A:$H,5,FALSE),IFERROR(VLOOKUP($A18,'[1]LD GmbH'!$A:$H,5,FALSE),IFERROR(VLOOKUP($A18,[1]Крисметал!$A:$H,5,FALSE),IFERROR(VLOOKUP($A18,[1]Унител!$A:$H,5,FALSE),"")))))) -> 0 | F18: =IFERROR(VLOOKUP($A18,[1]Други!$A:$H,6,FALSE),IFERROR(VLOOKUP($A18,[1]ИТТ!$A:$H,6,FALSE),IFERROR(VLOOKUP($A18,[1]Schrack!$A:$H,6,FALSE),IFERROR(VLOOKUP($A18,'[1]LD GmbH'!$A:$H,6,FALSE),IFERROR(VLOOKUP($A18,[1]Крисметал!$A:$H,6,FALSE),IFERROR(VLOOKUP($A18,[1]Унител!$A:$H,6,FALSE),"")))))) -> 4.07895 | G18: =IFERROR(SUMIF(Модули!$A:$A,Себестойност!A18,Модули!$B:$B),"") -> 200 | H18: =IFERROR(F18*G18,"") -> 815.79 | I18: =IFERROR(VLOOKUP($A18,[1]Други!$A:$H,8,FALSE),IFERROR(VLOOKUP($A18,[1]ИТТ!$A:$H,8,FALSE),IFERROR(VLOOKUP($A18,[1]Schrack!$A:$H,8,FALSE),IFERROR(VLOOKUP($A18,'[1]LD GmbH'!$A:$H,8,FALSE),IFERROR(VLOOKUP($A18,[1]Крисметал!$A:$H,8,FALSE),IFERROR(VLOOKUP($A18,[1]Унител!$A:$H,8,FALSE),"")))))) -> Suzhou VMA | J18: =IFERROR(VLOOKUP($A18,[1]Други!$A:$I,9,FALSE),IFERROR(VLOOKUP($A18,[1]ИТТ!$A:$I,9,FALSE),IFERROR(VLOOKUP($A18,[1]Schrack!$A:$I,9,FALSE),IFERROR(VLOOKUP($A18,'[1]LD GmbH'!$A:$I,9,FALSE),IFERROR(VLOOKUP($A18,[1]Крисметал!$A:$I,9,FALSE),IFERROR(VLOOKUP($A18,[1]Унител!$A:$I,9,FALSE),"")))))) -> 45645 | K18: =IFERROR(VLOOKUP($A18,[1]Други!$A:$H,7,FALSE),IFERROR(VLOOKUP($A18,[1]ИТТ!$A:$H,7,FALSE),IFERROR(VLOOKUP($A18,[1]Schrack!$A:$H,7,FALSE),IFERROR(VLOOKUP($A18,'[1]LD GmbH'!$A:$H,7,FALSE),IFERROR(VLOOKUP($A18,[1]Крисметал!$A:$H,7,FALSE),IFERROR(VLOOKUP($A18,[1]Унител!$A:$H,7,FALSE),"")))))) -> 4.89474 | L18: =G18*K18 -> 978.948 | O18: =SUMIF(Модули!$A:$A,Себестойност!A18,Модули!$B:$B)-G18 -> 0
A19: ПП тръба за т. вода Ф63/PN20 | B19: =IFERROR(VLOOKUP($A19,[1]Други!$A:$H,2,FALSE),IFERROR(VLOOKUP($A19,[1]ИТТ!$A:$H,2,FALSE),IFERROR(VLOOKUP($A19,[1]Schrack!$A:$H,2,FALSE),IFERROR(VLOOKUP($A19,'[1]LD GmbH'!$A:$H,2,FALSE),IFERROR(VLOOKUP($A19,[1]Крисметал!$A:$H,2,FALSE),IFERROR(VLOOKUP($A19,[1]Унител!$A:$H,2,FALSE),"")))))) -> 702 | C19: =IFERROR(VLOOKUP($A19,[1]Други!$A:$H,3,FALSE),IFERROR(VLOOKUP($A19,[1]ИТТ!$A:$H,3,FALSE),IFERROR(VLOOKUP($A19,[1]Schrack!$A:$H,3,FALSE),IFERROR(VLOOKUP($A19,'[1]LD GmbH'!$A:$H,3,FALSE),IFERROR(VLOOKUP($A19,[1]Крисметал!$A:$H,3,FALSE),IFERROR(VLOOKUP($A19,[1]Унител!$A:$H,3,FALSE),"")))))) -> 10.31787 | D19: =IFERROR(VLOOKUP($A19,[1]Други!$A:$H,4,FALSE),IFERROR(VLOOKUP($A19,[1]ИТТ!$A:$H,4,FALSE),IFERROR(VLOOKUP($A19,[1]Schrack!$A:$H,4,FALSE),IFERROR(VLOOKUP($A19,'[1]LD GmbH'!$A:$H,4,FALSE),IFERROR(VLOOKUP($A19,[1]Крисметал!$A:$H,4,FALSE),IFERROR(VLOOKUP($A19,[1]Унител!$A:$H,4,FALSE),"")))))) -> м. | E19: =IFERROR(VLOOKUP($A19,[1]Други!$A:$H,5,FALSE),IFERROR(VLOOKUP($A19,[1]ИТТ!$A:$H,5,FALSE),IFERROR(VLOOKUP($A19,[1]Schrack!$A:$H,5,FALSE),IFERROR(VLOOKUP($A19,'[1]LD GmbH'!$A:$H,5,FALSE),IFERROR(VLOOKUP($A19,[1]Крисметал!$A:$H,5,FALSE),IFERROR(VLOOKUP($A19,[1]Унител!$A:$H,5,FALSE),"")))))) -> 0 | F19: =IFERROR(VLOOKUP($A19,[1]Други!$A:$H,6,FALSE),IFERROR(VLOOKUP($A19,[1]ИТТ!$A:$H,6,FALSE),IFERROR(VLOOKUP($A19,[1]Schrack!$A:$H,6,FALSE),IFERROR(VLOOKUP($A19,'[1]LD GmbH'!$A:$H,6,FALSE),IFERROR(VLOOKUP($A19,[1]Крисметал!$A:$H,6,FALSE),IFERROR(VLOOKUP($A19,[1]Унител!$A:$H,6,FALSE),"")))))) -> 10.31787 | G19: =IFERROR(SUMIF(Модули!$A:$A,Себестойност!A19,Модули!$B:$B),"") -> 12 | H19: =IFERROR(F19*G19,"") -> 123.81444 | I19: =IFERROR(VLOOKUP($A19,[1]Други!$A:$H,8,FALSE),IFERROR(VLOOKUP($A19,[1]ИТТ!$A:$H,8,FALSE),IFERROR(VLOOKUP($A19,[1]Schrack!$A:$H,8,FALSE),IFERROR(VLOOKUP($A19,'[1]LD GmbH'!$A:$H,8,FALSE),IFERROR(VLOOKUP($A19,[1]Крисметал!$A:$H,8,FALSE),IFERROR(VLOOKUP($A19,[1]Унител!$A:$H,8,FALSE),"")))))) -> ИВДА-ГЕО | J19: =IFERROR(VLOOKUP($A19,[1]Други!$A:$I,9,FALSE),IFERROR(VLOOKUP($A19,[1]ИТТ!$A:$I,9,FALSE),IFERROR(VLOOKUP($A19,[1]Schrack!$A:$I,9,FALSE),IFERROR(VLOOKUP($A19,'[1]LD GmbH'!$A:$I,9,FALSE),IFERROR(VLOOKUP($A19,[1]Крисметал!$A:$I,9,FALSE),IFERROR(VLOOKUP($A19,[1]Унител!$A:$I,9,FALSE),"")))))) -> 44959 | K19: =IFERROR(VLOOKUP($A19,[1]Други!$A:$H,7,FALSE),IFERROR(VLOOKUP($A19,[1]ИТТ!$A:$H,7,FALSE),IFERROR(VLOOKUP($A19,[1]Schrack!$A:$H,7,FALSE),IFERROR(VLOOKUP($A19,'[1]LD GmbH'!$A:$H,7,FALSE),IFERROR(VLOOKUP($A19,[1]Крисметал!$A:$H,7,FALSE),IFERROR(VLOOKUP($A19,[1]Унител!$A:$H,7,FALSE),"")))))) -> 12.381444 | L19: =G19*K19 -> 148.57733 | O19: =SUMIF(Модули!$A:$A,Себестойност!A19,Модули!$B:$B)-G19 -> 0
A20: ПОДПОРА ПОЛИАМИД + СТОПЕР
A21: Полиамид | B21: =IFERROR(VLOOKUP($A21,[1]Други!$A:$H,2,FALSE),IFERROR(VLOOKUP($A21,[1]ИТТ!$A:$H,2,FALSE),IFERROR(VLOOKUP($A21,[1]Schrack!$A:$H,2,FALSE),IFERROR(VLOOKUP($A21,'[1]LD GmbH'!$A:$H,2,FALSE),IFERROR(VLOOKUP($A21,[1]Крисметал!$A:$H,2,FALSE),IFERROR(VLOOKUP($A21,[1]Унител!$A:$H,2,FALSE),"")))))) -> - | C21: =IFERROR(VLOOKUP($A21,[1]Други!$A:$H,3,FALSE),IFERROR(VLOOKUP($A21,[1]ИТТ!$A:$H,3,FALSE),IFERROR(VLOOKUP($A21,[1]Schrack!$A:$H,3,FALSE),IFERROR(VLOOKUP($A21,'[1]LD GmbH'!$A:$H,3,FALSE),IFERROR(VLOOKUP($A21,[1]Крисметал!$A:$H,3,FALSE),IFERROR(VLOOKUP($A21,[1]Унител!$A:$H,3,FALSE),"")))))) -> 1057.6584 | D21: =IFERROR(VLOOKUP($A21,[1]Други!$A:$H,4,FALSE),IFERROR(VLOOKUP($A21,[1]ИТТ!$A:$H,4,FALSE),IFERROR(VLOOKUP($A21,[1]Schrack!$A:$H,4,FALSE),IFERROR(VLOOKUP($A21,'[1]LD GmbH'!$A:$H,4,FALSE),IFERROR(VLOOKUP($A21,[1]Крисметал!$A:$H,4,FALSE),IFERROR(VLOOKUP($A21,[1]Унител!$A:$H,4,FALSE),"")))))) -> бр. | E21: =IFERROR(VLOOKUP($A21,[1]Други!$A:$H,5,FALSE),IFERROR(VLOOKUP($A21,[1]ИТТ!$A:$H,5,FALSE),IFERROR(VLOOKUP($A21,[1]Schrack!$A:$H,5,FALSE),IFERROR(VLOOKUP($A21,'[1]LD GmbH'!$A:$H,5,FALSE),IFERROR(VLOOKUP($A21,[1]Крисметал!$A:$H,5,FALSE),IFERROR(VLOOKUP($A21,[1]Унител!$A:$H,5,FALSE),"")))))) -> 0 | F21: =IFERROR(VLOOKUP($A21,[1]Други!$A:$H,6,FALSE),IFERROR(VLOOKUP($A21,[1]ИТТ!$A:$H,6,FALSE),IFERROR(VLOOKUP($A21,[1]Schrack!$A:$H,6,FALSE),IFERROR(VLOOKUP($A21,'[1]LD GmbH'!$A:$H,6,FALSE),IFERROR(VLOOKUP($A21,[1]Крисметал!$A:$H,6,FALSE),IFERROR(VLOOKUP($A21,[1]Унител!$A:$H,6,FALSE),"")))))) -> 1057.6584 | G21: =IFERROR(SUMIF(Модули!$A:$A,Себестойност!A21,Модули!$B:$B),"") -> 1 | H21: =IFERROR(F21*G21,"") -> 1057.6584 | I21: =IFERROR(VLOOKUP($A21,[1]Други!$A:$H,8,FALSE),IFERROR(VLOOKUP($A21,[1]ИТТ!$A:$H,8,FALSE),IFERROR(VLOOKUP($A21,[1]Schrack!$A:$H,8,FALSE),IFERROR(VLOOKUP($A21,'[1]LD GmbH'!$A:$H,8,FALSE),IFERROR(VLOOKUP($A21,[1]Крисметал!$A:$H,8,FALSE),IFERROR(VLOOKUP($A21,[1]Унител!$A:$H,8,FALSE),"")))))) -> Гумпласт | J21: =IFERROR(VLOOKUP($A21,[1]Други!$A:$I,9,FALSE),IFERROR(VLOOKUP($A21,[1]ИТТ!$A:$I,9,FALSE),IFERROR(VLOOKUP($A21,[1]Schrack!$A:$I,9,FALSE),IFERROR(VLOOKUP($A21,'[1]LD GmbH'!$A:$I,9,FALSE),IFERROR(VLOOKUP($A21,[1]Крисметал!$A:$I,9,FALSE),IFERROR(VLOOKUP($A21,[1]Унител!$A:$I,9,FALSE),"")))))) -> 45635 | K21: =IFERROR(VLOOKUP($A21,[1]Други!$A:$H,7,FALSE),IFERROR(VLOOKUP($A21,[1]ИТТ!$A:$H,7,FALSE),IFERROR(VLOOKUP($A21,[1]Schrack!$A:$H,7,FALSE),IFERROR(VLOOKUP($A21,'[1]LD GmbH'!$A:$H,7,FALSE),IFERROR(VLOOKUP($A21,[1]Крисметал!$A:$H,7,FALSE),IFERROR(VLOOKUP($A21,[1]Унител!$A:$H,7,FALSE),"")))))) -> 1269.1901 | L21: =G21*K21 -> 1269.1901 | O21: =SUMIF(Модули!$A:$A,Себестойност!A21,Модули!$B:$B)-G21 -> 0
A22: Шпилка, DIN 976, 10.9, Bl., M 16 x 2000 | B22: =IFERROR(VLOOKUP($A22,[1]Други!$A:$H,2,FALSE),IFERROR(VLOOKUP($A22,[1]ИТТ!$A:$H,2,FALSE),IFERROR(VLOOKUP($A22,[1]Schrack!$A:$H,2,FALSE),IFERROR(VLOOKUP($A22,'[1]LD GmbH'!$A:$H,2,FALSE),IFERROR(VLOOKUP($A22,[1]Крисметал!$A:$H,2,FALSE),IFERROR(VLOOKUP($A22,[1]Унител!$A:$H,2,FALSE),"")))))) -> 00975 1000 16 2000 | C22: =IFERROR(VLOOKUP($A22,[1]Други!$A:$H,3,FALSE),IFERROR(VLOOKUP($A22,[1]ИТТ!$A:$H,3,FALSE),IFERROR(VLOOKUP($A22,[1]Schrack!$A:$H,3,FALSE),IFERROR(VLOOKUP($A22,'[1]LD GmbH'!$A:$H,3,FALSE),IFERROR(VLOOKUP($A22,[1]Крисметал!$A:$H,3,FALSE),IFERROR(VLOOKUP($A22,[1]Унител!$A:$H,3,FALSE),"")))))) -> 824.65245 | D22: =IFERROR(VLOOKUP($A22,[1]Други!$A:$H,4,FALSE),IFERROR(VLOOKUP($A22,[1]ИТТ!$A:$H,4,FALSE),IFERROR(VLOOKUP($A22,[1]Schrack!$A:$H,4,FALSE),IFERROR(VLOOKUP($A22,'[1]LD GmbH'!$A:$H,4,FALSE),IFERROR(VLOOKUP($A22,[1]Крисметал!$A:$H,4,FALSE),IFERROR(VLOOKUP($A22,[1]Унител!$A:$H,4,FALSE),"")))))) -> 100 бр. | E22: =IFERROR(VLOOKUP($A22,[1]Други!$A:$H,5,FALSE),IFERROR(VLOOKUP($A22,[1]ИТТ!$A:$H,5,FALSE),IFERROR(VLOOKUP($A22,[1]Schrack!$A:$H,5,FALSE),IFERROR(VLOOKUP($A22,'[1]LD GmbH'!$A:$H,5,FALSE),IFERROR(VLOOKUP($A22,[1]Крисметал!$A:$H,5,FALSE),IFERROR(VLOOKUP($A22,[1]Унител!$A:$H,5,FALSE),"")))))) -> 0 | F22: =IFERROR(VLOOKUP($A22,[1]Други!$A:$H,6,FALSE),IFERROR(VLOOKUP($A22,[1]ИТТ!$A:$H,6,FALSE),IFERROR(VLOOKUP($A22,[1]Schrack!$A:$H,6,FALSE),IFERROR(VLOOKUP($A22,'[1]LD GmbH'!$A:$H,6,FALSE),IFERROR(VLOOKUP($A22,[1]Крисметал!$A:$H,6,FALSE),IFERROR(VLOOKUP($A22,[1]Унител!$A:$H,6,FALSE),"")))))) -> 824.65245 | G22: =IFERROR(SUMIF(Модули!$A:$A,Себестойност!A22,Модули!$B:$B),"") -> 0.04 | H22: =IFERROR(F22*G22,"") -> 32.986098 | I22: =IFERROR(VLOOKUP($A22,[1]Други!$A:$H,8,FALSE),IFERROR(VLOOKUP($A22,[1]ИТТ!$A:$H,8,FALSE),IFERROR(VLOOKUP($A22,[1]Schrack!$A:$H,8,FALSE),IFERROR(VLOOKUP($A22,'[1]LD GmbH'!$A:$H,8,FALSE),IFERROR(VLOOKUP($A22,[1]Крисметал!$A:$H,8,FALSE),IFERROR(VLOOKUP($A22,[1]Унител!$A:$H,8,FALSE),"")))))) -> ИТТ | J22: =IFERROR(VLOOKUP($A22,[1]Други!$A:$I,9,FALSE),IFERROR(VLOOKUP($A22,[1]ИТТ!$A:$I,9,FALSE),IFERROR(VLOOKUP($A22,[1]Schrack!$A:$I,9,FALSE),IFERROR(VLOOKUP($A22,'[1]LD GmbH'!$A:$I,9,FALSE),IFERROR(VLOOKUP($A22,[1]Крисметал!$A:$I,9,FALSE),IFERROR(VLOOKUP($A22,[1]Унител!$A:$I,9,FALSE),"")))))) -> 45642 | K22: =IFERROR(VLOOKUP($A22,[1]Други!$A:$H,7,FALSE),IFERROR(VLOOKUP($A22,[1]ИТТ!$A:$H,7,FALSE),IFERROR(VLOOKUP($A22,[1]Schrack!$A:$H,7,FALSE),IFERROR(VLOOKUP($A22,'[1]LD GmbH'!$A:$H,7,FALSE),IFERROR(VLOOKUP($A22,[1]Крисметал!$A:$H,7,FALSE),IFERROR(VLOOKUP($A22,[1]Унител!$A:$H,7,FALSE),"")))))) -> 989.58294 | L22: =G22*K22 -> 39.583318 | O22: =SUMIF(Модули!$A:$A,Себестойност!A22,Модули!$B:$B)-G22 -> 0
A23: Гайка самоосигурителна, DIN 985, 10, vZn, M16 | B23: =IFERROR(VLOOKUP($A23,[1]Други!$A:$H,2,FALSE),IFERROR(VLOOKUP($A23,[1]ИТТ!$A:$H,2,FALSE),IFERROR(VLOOKUP($A23,[1]Schrack!$A:$H,2,FALSE),IFERROR(VLOOKUP($A23,'[1]LD GmbH'!$A:$H,2,FALSE),IFERROR(VLOOKUP($A23,[1]Крисметал!$A:$H,2,FALSE),IFERROR(VLOOKUP($A23,[1]Унител!$A:$H,2,FALSE),"")))))) -> 00985 1001 16 | C23: =IFERROR(VLOOKUP($A23,[1]Други!$A:$H,3,FALSE),IFERROR(VLOOKUP($A23,[1]ИТТ!$A:$H,3,FALSE),IFERROR(VLOOKUP($A23,[1]Schrack!$A:$H,3,FALSE),IFERROR(VLOOKUP($A23,'[1]LD GmbH'!$A:$H,3,FALSE),IFERROR(VLOOKUP($A23,[1]Крисметал!$A:$H,3,FALSE),IFERROR(VLOOKUP($A23,[1]Унител!$A:$H,3,FALSE),"")))))) -> 37.804922 | D23: =IFERROR(VLOOKUP($A23,[1]Други!$A:$H,4,FALSE),IFERROR(VLOOKUP($A23,[1]ИТТ!$A:$H,4,FALSE),IFERROR(VLOOKUP($A23,[1]Schrack!$A:$H,4,FALSE),IFERROR(VLOOKUP($A23,'[1]LD GmbH'!$A:$H,4,FALSE),IFERROR(VLOOKUP($A23,[1]Крисметал!$A:$H,4,FALSE),IFERROR(VLOOKUP($A23,[1]Унител!$A:$H,4,FALSE),"")))))) -> 100 бр. | E23: =IFERROR(VLOOKUP($A23,[1]Други!$A:$H,5,FALSE),IFERROR(VLOOKUP($A23,[1]ИТТ!$A:$H,5,FALSE),IFERROR(VLOOKUP($A23,[1]Schrack!$A:$H,5,FALSE),IFERROR(VLOOKUP($A23,'[1]LD GmbH'!$A:$H,5,FALSE),IFERROR(VLOOKUP($A23,[1]Крисметал!$A:$H,5,FALSE),IFERROR(VLOOKUP($A23,[1]Унител!$A:$H,5,FALSE),"")))))) -> 0 | F23: =IFERROR(VLOOKUP($A23,[1]Други!$A:$H,6,FALSE),IFERROR(VLOOKUP($A23,[1]ИТТ!$A:$H,6,FALSE),IFERROR(VLOOKUP($A23,[1]Schrack!$A:$H,6,FALSE),IFERROR(VLOOKUP($A23,'[1]LD GmbH'!$A:$H,6,FALSE),IFERROR(VLOOKUP($A23,[1]Крисметал!$A:$H,6,FALSE),IFERROR(VLOOKUP($A23,[1]Унител!$A:$H,6,FALSE),"")))))) -> 37.804922 | G23: =IFERROR(SUMIF(Модули!$A:$A,Себестойност!A23,Модули!$B:$B),"") -> 0.05 | H23: =IFERROR(F23*G23,"") -> 1.8902461 | I23: =IFERROR(VLOOKUP($A23,[1]Други!$A:$H,8,FALSE),IFERROR(VLOOKUP($A23,[1]ИТТ!$A:$H,8,FALSE),IFERROR(VLOOKUP($A23,[1]Schrack!$A:$H,8,FALSE),IFERROR(VLOOKUP($A23,'[1]LD GmbH'!$A:$H,8,FALSE),IFERROR(VLOOKUP($A23,[1]Крисметал!$A:$H,8,FALSE),IFERROR(VLOOKUP($A23,[1]Унител!$A:$H,8,FALSE),"")))))) -> ИТТ | J23: =IFERROR(VLOOKUP($A23,[1]Други!$A:$I,9,FALSE),IFERROR(VLOOKUP($A23,[1]ИТТ!$A:$I,9,FALSE),IFERROR(VLOOKUP($A23,[1]Schrack!$A:$I,9,FALSE),IFERROR(VLOOKUP($A23,'[1]LD GmbH'!$A:$I,9,FALSE),IFERROR(VLOOKUP($A23,[1]Крисметал!$A:$I,9,FALSE),IFERROR(VLOOKUP($A23,[1]Унител!$A:$I,9,FALSE),"")))))) -> 45642 | K23: =IFERROR(VLOOKUP($A23,[1]Други!$A:$H,7,FALSE),IFERROR(VLOOKUP($A23,[1]ИТТ!$A:$H,7,FALSE),IFERROR(VLOOKUP($A23,[1]Schrack!$A:$H,7,FALSE),IFERROR(VLOOKUP($A23,'[1]LD GmbH'!$A:$H,7,FALSE),IFERROR(VLOOKUP($A23,[1]Крисметал!$A:$H,7,FALSE),IFERROR(VLOOKUP($A23,[1]Унител!$A:$H,7,FALSE),"")))))) -> 45.365906 | L23: =G23*K23 -> 2.2682953 | O23: =SUMIF(Модули!$A:$A,Себестойност!A23,Модули!$B:$B)-G23 -> 0
A24: Болт за дърво, Din 571, vZn, ф8 х 100 | B24: =IFERROR(VLOOKUP($A24,[1]Други!$A:$H,2,FALSE),IFERROR(VLOOKUP($A24,[1]ИТТ!$A:$H,2,FALSE),IFERROR(VLOOKUP($A24,[1]Schrack!$A:$H,2,FALSE),IFERROR(VLOOKUP($A24,'[1]LD GmbH'!$A:$H,2,FALSE),IFERROR(VLOOKUP($A24,[1]Крисметал!$A:$H,2,FALSE),IFERROR(VLOOKUP($A24,[1]Унител!$A:$H,2,FALSE),"")))))) -> 00571 0001 8 100 | C24: =IFERROR(VLOOKUP($A24,[1]Други!$A:$H,3,FALSE),IFERROR(VLOOKUP($A24,[1]ИТТ!$A:$H,3,FALSE),IFERROR(VLOOKUP($A24,[1]Schrack!$A:$H,3,FALSE),IFERROR(VLOOKUP($A24,'[1]LD GmbH'!$A:$H,3,FALSE),IFERROR(VLOOKUP($A24,[1]Крисметал!$A:$H,3,FALSE),IFERROR(VLOOKUP($A24,[1]Унител!$A:$H,3,FALSE),"")))))) -> 0.09 | D24: =IFERROR(VLOOKUP($A24,[1]Други!$A:$H,4,FALSE),IFERROR(VLOOKUP($A24,[1]ИТТ!$A:$H,4,FALSE),IFERROR(VLOOKUP($A24,[1]Schrack!$A:$H,4,FALSE),IFERROR(VLOOKUP($A24,'[1]LD GmbH'!$A:$H,4,FALSE),IFERROR(VLOOKUP($A24,[1]Крисметал!$A:$H,4,FALSE),IFERROR(VLOOKUP($A24,[1]Унител!$A:$H,4,FALSE),"")))))) -> бр. | E24: =IFERROR(VLOOKUP($A24,[1]Други!$A:$H,5,FALSE),IFERROR(VLOOKUP($A24,[1]ИТТ!$A:$H,5,FALSE),IFERROR(VLOOKUP($A24,[1]Schrack!$A:$H,5,FALSE),IFERROR(VLOOKUP($A24,'[1]LD GmbH'!$A:$H,5,FALSE),IFERROR(VLOOKUP($A24,[1]Крисметал!$A:$H,5,FALSE),IFERROR(VLOOKUP($A24,[1]Унител!$A:$H,5,FALSE),"")))))) -> 0 | F24: =IFERROR(VLOOKUP($A24,[1]Други!$A:$H,6,FALSE),IFERROR(VLOOKUP($A24,[1]ИТТ!$A:$H,6,FALSE),IFERROR(VLOOKUP($A24,[1]Schrack!$A:$H,6,FALSE),IFERROR(VLOOKUP($A24,'[1]LD GmbH'!$A:$H,6,FALSE),IFERROR(VLOOKUP($A24,[1]Крисметал!$A:$H,6,FALSE),IFERROR(VLOOKUP($A24,[1]Унител!$A:$H,6,FALSE),"")))))) -> 0.09 | G24: =IFERROR(SUMIF(Модули!$A:$A,Себестойност!A24,Модули!$B:$B),"") -> 0.12 | H24: =IFERROR(F24*G24,"") -> 0.0108 | I24: =IFERROR(VLOOKUP($A24,[1]Други!$A:$H,8,FALSE),IFERROR(VLOOKUP($A24,[1]ИТТ!$A:$H,8,FALSE),IFERROR(VLOOKUP($A24,[1]Schrack!$A:$H,8,FALSE),IFERROR(VLOOKUP($A24,'[1]LD GmbH'!$A:$H,8,FALSE),IFERROR(VLOOKUP($A24,[1]Крисметал!$A:$H,8,FALSE),IFERROR(VLOOKUP($A24,[1]Унител!$A:$H,8,FALSE),"")))))) -> ИТТ | J24: =IFERROR(VLOOKUP($A24,[1]Други!$A:$I,9,FALSE),IFERROR(VLOOKUP($A24,[1]ИТТ!$A:$I,9,FALSE),IFERROR(VLOOKUP($A24,[1]Schrack!$A:$I,9,FALSE),IFERROR(VLOOKUP($A24,'[1]LD GmbH'!$A:$I,9,FALSE),IFERROR(VLOOKUP($A24,[1]Крисметал!$A:$I,9,FALSE),IFERROR(VLOOKUP($A24,[1]Унител!$A:$I,9,FALSE),"")))))) -> 0 | K24: =IFERROR(VLOOKUP($A24,[1]Други!$A:$H,7,FALSE),IFERROR(VLOOKUP($A24,[1]ИТТ!$A:$H,7,FALSE),IFERROR(VLOOKUP($A24,[1]Schrack!$A:$H,7,FALSE),IFERROR(VLOOKUP($A24,'[1]LD GmbH'!$A:$H,7,FALSE),IFERROR(VLOOKUP($A24,[1]Крисметал!$A:$H,7,FALSE),IFERROR(VLOOKUP($A24,[1]Унител!$A:$H,7,FALSE),"")))))) -> 0.108 | L24: =G24*K24 -> 0.01296 | O24: =SUMIF(Модули!$A:$A,Себестойност!A24,Модули!$B:$B)-G24 -> 0
A25: УСЛУГИ
A26: Транспорт ДУНАВ-СВ (Притискаща плоча) | B26: =IFERROR(VLOOKUP($A26,[1]Други!$A:$H,2,FALSE),IFERROR(VLOOKUP($A26,[1]ИТТ!$A:$H,2,FALSE),IFERROR(VLOOKUP($A26,[1]Schrack!$A:$H,2,FALSE),IFERROR(VLOOKUP($A26,'[1]LD GmbH'!$A:$H,2,FALSE),IFERROR(VLOOKUP($A26,[1]Крисметал!$A:$H,2,FALSE),IFERROR(VLOOKUP($A26,[1]Унител!$A:$H,2,FALSE),"")))))) -> 080155 | C26: =IFERROR(VLOOKUP($A26,[1]Други!$A:$H,3,FALSE),IFERROR(VLOOKUP($A26,[1]ИТТ!$A:$H,3,FALSE),IFERROR(VLOOKUP($A26,[1]Schrack!$A:$H,3,FALSE),IFERROR(VLOOKUP($A26,'[1]LD GmbH'!$A:$H,3,FALSE),IFERROR(VLOOKUP($A26,[1]Крисметал!$A:$H,3,FALSE),IFERROR(VLOOKUP($A26,[1]Унител!$A:$H,3,FALSE),"")))))) -> 102.25838 | D26: =IFERROR(VLOOKUP($A26,[1]Други!$A:$H,4,FALSE),IFERROR(VLOOKUP($A26,[1]ИТТ!$A:$H,4,FALSE),IFERROR(VLOOKUP($A26,[1]Schrack!$A:$H,4,FALSE),IFERROR(VLOOKUP($A26,'[1]LD GmbH'!$A:$H,4,FALSE),IFERROR(VLOOKUP($A26,[1]Крисметал!$A:$H,4,FALSE),IFERROR(VLOOKUP($A26,[1]Унител!$A:$H,4,FALSE),"")))))) -> бр. | E26: =IFERROR(VLOOKUP($A26,[1]Други!$A:$H,5,FALSE),IFERROR(VLOOKUP($A26,[1]ИТТ!$A:$H,5,FALSE),IFERROR(VLOOKUP($A26,[1]Schrack!$A:$H,5,FALSE),IFERROR(VLOOKUP($A26,'[1]LD GmbH'!$A:$H,5,FALSE),IFERROR(VLOOKUP($A26,[1]Крисметал!$A:$H,5,FALSE),IFERROR(VLOOKUP($A26,[1]Унител!$A:$H,5,FALSE),"")))))) -> 0 | F26: =IFERROR(VLOOKUP($A26,[1]Други!$A:$H,6,FALSE),IFERROR(VLOOKUP($A26,[1]ИТТ!$A:$H,6,FALSE),IFERROR(VLOOKUP($A26,[1]Schrack!$A:$H,6,FALSE),IFERROR(VLOOKUP($A26,'[1]LD GmbH'!$A:$H,6,FALSE),IFERROR(VLOOKUP($A26,[1]Крисметал!$A:$H,6,FALSE),IFERROR(VLOOKUP($A26,[1]Унител!$A:$H,6,FALSE),"")))))) -> 102.25838 | G26: =IFERROR(SUMIF(Модули!$A:$A,Себестойност!A26,Модули!$B:$B),"") -> 1 | H26: =IFERROR(F26*G26,"") -> 102.25838 | I26: =IFERROR(VLOOKUP($A26,[1]Други!$A:$H,8,FALSE),IFERROR(VLOOKUP($A26,[1]ИТТ!$A:$H,8,FALSE),IFERROR(VLOOKUP($A26,[1]Schrack!$A:$H,8,FALSE),IFERROR(VLOOKUP($A26,'[1]LD GmbH'!$A:$H,8,FALSE),IFERROR(VLOOKUP($A26,[1]Крисметал!$A:$H,8,FALSE),IFERROR(VLOOKUP($A26,[1]Унител!$A:$H,8,FALSE),"")))))) -> ДУНОВ-СВ | J26: =IFERROR(VLOOKUP($A26,[1]Други!$A:$I,9,FALSE),IFERROR(VLOOKUP($A26,[1]ИТТ!$A:$I,9,FALSE),IFERROR(VLOOKUP($A26,[1]Schrack!$A:$I,9,FALSE),IFERROR(VLOOKUP($A26,'[1]LD GmbH'!$A:$I,9,FALSE),IFERROR(VLOOKUP($A26,[1]Крисметал!$A:$I,9,FALSE),IFERROR(VLOOKUP($A26,[1]Унител!$A:$I,9,FALSE),"")))))) -> 45315 | K26: =IFERROR(VLOOKUP($A26,[1]Други!$A:$H,7,FALSE),IFERROR(VLOOKUP($A26,[1]ИТТ!$A:$H,7,FALSE),IFERROR(VLOOKUP($A26,[1]Schrack!$A:$H,7,FALSE),IFERROR(VLOOKUP($A26,'[1]LD GmbH'!$A:$H,7,FALSE),IFERROR(VLOOKUP($A26,[1]Крисметал!$A:$H,7,FALSE),IFERROR(VLOOKUP($A26,[1]Унител!$A:$H,7,FALSE),"")))))) -> 122.71005 | L26: =G26*K26 -> 122.71005 | O26: =SUMIF(Модули!$A:$A,Себестойност!A26,Модули!$B:$B)-G26 -> 0
A27: ВОДНО Рязане метал (Притискаща плоча 100mm) | B27: =IFERROR(VLOOKUP($A27,[1]Други!$A:$H,2,FALSE),IFERROR(VLOOKUP($A27,[1]ИТТ!$A:$H,2,FALSE),IFERROR(VLOOKUP($A27,[1]Schrack!$A:$H,2,FALSE),IFERROR(VLOOKUP($A27,'[1]LD GmbH'!$A:$H,2,FALSE),IFERROR(VLOOKUP($A27,[1]Крисметал!$A:$H,2,FALSE),IFERROR(VLOOKUP($A27,[1]Унител!$A:$H,2,FALSE),"")))))) -> - | C27: =IFERROR(VLOOKUP($A27,[1]Други!$A:$H,3,FALSE),IFERROR(VLOOKUP($A27,[1]ИТТ!$A:$H,3,FALSE),IFERROR(VLOOKUP($A27,[1]Schrack!$A:$H,3,FALSE),IFERROR(VLOOKUP($A27,'[1]LD GmbH'!$A:$H,3,FALSE),IFERROR(VLOOKUP($A27,[1]Крисметал!$A:$H,3,FALSE),IFERROR(VLOOKUP($A27,[1]Унител!$A:$H,3,FALSE),"")))))) -> 2556.4594 | D27: =IFERROR(VLOOKUP($A27,[1]Други!$A:$H,4,FALSE),IFERROR(VLOOKUP($A27,[1]ИТТ!$A:$H,4,FALSE),IFERROR(VLOOKUP($A27,[1]Schrack!$A:$H,4,FALSE),IFERROR(VLOOKUP($A27,'[1]LD GmbH'!$A:$H,4,FALSE),IFERROR(VLOOKUP($A27,[1]Крисметал!$A:$H,4,FALSE),IFERROR(VLOOKUP($A27,[1]Унител!$A:$H,4,FALSE),"")))))) -> бр. | E27: =IFERROR(VLOOKUP($A27,[1]Други!$A:$H,5,FALSE),IFERROR(VLOOKUP($A27,[1]ИТТ!$A:$H,5,FALSE),IFERROR(VLOOKUP($A27,[1]Schrack!$A:$H,5,FALSE),IFERROR(VLOOKUP($A27,'[1]LD GmbH'!$A:$H,5,FALSE),IFERROR(VLOOKUP($A27,[1]Крисметал!$A:$H,5,FALSE),IFERROR(VLOOKUP($A27,[1]Унител!$A:$H,5,FALSE),"")))))) -> 0 | F27: =IFERROR(VLOOKUP($A27,[1]Други!$A:$H,6,FALSE),IFERROR(VLOOKUP($A27,[1]ИТТ!$A:$H,6,FALSE),IFERROR(VLOOKUP($A27,[1]Schrack!$A:$H,6,FALSE),IFERROR(VLOOKUP($A27,'[1]LD GmbH'!$A:$H,6,FALSE),IFERROR(VLOOKUP($A27,[1]Крисметал!$A:$H,6,FALSE),IFERROR(VLOOKUP($A27,[1]Унител!$A:$H,6,FALSE),"")))))) -> 2556.4594 | G27: =IFERROR(SUMIF(Модули!$A:$A,Себестойност!A27,Модули!$B:$B),"") -> 2 | H27: =IFERROR(F27*G27,"") -> 5112.9188 | I27: =IFERROR(VLOOKUP($A27,[1]Други!$A:$H,8,FALSE),IFERROR(VLOOKUP($A27,[1]ИТТ!$A:$H,8,FALSE),IFERROR(VLOOKUP($A27,[1]Schrack!$A:$H,8,FALSE),IFERROR(VLOOKUP($A27,'[1]LD GmbH'!$A:$H,8,FALSE),IFERROR(VLOOKUP($A27,[1]Крисметал!$A:$H,8,FALSE),IFERROR(VLOOKUP($A27,[1]Унител!$A:$H,8,FALSE),"")))))) -> Джусита-ДЕС | J27: =IFERROR(VLOOKUP($A27,[1]Други!$A:$I,9,FALSE),IFERROR(VLOOKUP($A27,[1]ИТТ!$A:$I,9,FALSE),IFERROR(VLOOKUP($A27,[1]Schrack!$A:$I,9,FALSE),IFERROR(VLOOKUP($A27,'[1]LD GmbH'!$A:$I,9,FALSE),IFERROR(VLOOKUP($A27,[1]Крисметал!$A:$I,9,FALSE),IFERROR(VLOOKUP($A27,[1]Унител!$A:$I,9,FALSE),"")))))) -> 45642 | K27: =IFERROR(VLOOKUP($A27,[1]Други!$A:$H,7,FALSE),IFERROR(VLOOKUP($A27,[1]ИТТ!$A:$H,7,FALSE),IFERROR(VLOOKUP($A27,[1]Schrack!$A:$H,7,FALSE),IFERROR(VLOOKUP($A27,'[1]LD GmbH'!$A:$H,7,FALSE),IFERROR(VLOOKUP($A27,[1]Крисметал!$A:$H,7,FALSE),IFERROR(VLOOKUP($A27,[1]Унител!$A:$H,7,FALSE),"")))))) -> 3067.7513 | L27: =G27*K27 -> 6135.5026 | O27: =SUMIF(Модули!$A:$A,Себестойност!A27,Модули!$B:$B)-G27 -> 0
